Workbook

Sheet 最高报价汇总 
B2: 新元促销利率 | F2: 46099 | G2: =F2-7 -> 46092
B3: Bank | C3: 1M | D3: 3M | E3: 6M | F3: 9M | G3: 12M | H3: 18M | I3: 24M | J3: Minimum Amount | K3: Others | L3: 代表本周有调整
B4: BOC | C4: =SGD促销!C11 -> 0.011 | D4: =SGD促销!C29 -> 0.013 | E4: =SGD促销!C47 -> 0.0135 | F4: =SGD促销!C76 -> 0.012 | G4: =SGD促销!C102 -> 0.014 | H4: =[1]SGD促销!C124 -> - | I4: =[1]SGD促销!Q133 -> - | J4: 500 | K4: 手机银行
B5: BEA | C5: =SGD促销!C7 -> - | D5: =SGD促销!C27 -> 0.0135 | E5: - | F5: - | G5: =SGD促销!C109 -> 0.013 | H5: - | I5: - | J5: =SGD促销!EZ7 -> 100,000 < 2,000,000 | K5: 新资金（有网银和手机银行）
B6: CIMB | C6: - | D6: =SGD促销!C18 -> 0.0125 | E6: =SGD促销!C51 -> 0.013 | F6: =SGD促销!C78 -> 0.011 | G6: =SGD促销!C96 -> 0.013 | I6: - | J6: 10,000-1,000,000 | K6: 电子银行,Preferrec Banking personal banking -0.05% 按促销/挂牌利率续存
B7: ICBC | C7: =SGD促销!C9 -> 0.0115 | D7: =SGD促销!C25 -> 0.0135 | E7: =SGD促销!C45 -> 0.0115 | F7: =SGD促销!C74 -> 0.0105 | G7: =SGD促销!C104 -> 0.0105 | H7: - | I7: - | J7: 500 | K7: 柜面2万起存，利率-0.10%，电子银行500起存 按挂牌利率续存
B8: SingFinance | C8: =SGD促销!C13 -> 0.0105 | D8: =SGD促销!C31 -> 0.0125 | E8: =SGD促销!C54 -> 0.0125 | F8: - | G8: =SGD促销!C108 -> - | H8: - | I8: - | J8: 10000 | K8: Fresh FunCs, Online Placement
B9: CITI | C9: - | D9: =SGD促销!C22 -> 0.0125 | E9: =SGD促销!C64 -> 0.0115 | F9: - | G9: - | H9: - | I9: - | J9: 10,000-5,000,000 | K9: 新资金,citi banking customer，counter only 按挂牌利率续存
B10: SCB | C10: - | D10: - | E10: - | F10: =SGD促销!C85 -> 0.011 | G10: - | H10: - | I10: - | J10: 25000 | K10: 新资金&电子银行（网银/手机） 按挂牌利率续存
B11: SBI | C11: - | D11: - | E11: =SGD促销!C43 -> 0.0115 | F11: - | G11: =SGD促销!C100 -> 0.008 | H11: - | I11: - | J11: $50,000-1,000,000 | K11: 按挂牌利率续存 $5k - 1mil
B12: HSBC | C12: =SGD促销!C8 -> 0.006 | D12: =SGD促销!C28 -> 0.014 | E12: =SGD促销!C63 -> 0.0075 | F12: - | G12: =SGD促销!C113 -> 0.0085 | H12: - | I12: - | J12: 30000 | K12: PERSONAL CUSTOMER FRESH FUNc Mobile only
B13: RHB | C13: - | D13: =SGD促销!C23 -> 0.012 | E13: =SGD促销!C49 -> 0.012 | F13: - | G13: =SGD促销!C94 -> 0.0125 | H13: =[1]SGD促销!C128 -> - | I13: - | J13: 20000 | K13: 以上利率适用于PREMIER BANKING（AUM 20万） PERSONAL BANKING利率-0.10% APP 按促销利率续存
B14: Maybank | E14: =SGD促销!C56 -> 0.013 | F14: =SGD促销!C83 -> 0.0132 | G14: =SGD促销!C98 -> 0.0132 | H14: =[1]SGD促销!C126 -> - | I14: =[1]SGD促销!Q135 -> - | J14: 20000 | K14: savings Buncle，要求每存入1k新元活期存款，可有10k定期存款享有以上优惠利率（活期资金会被冻结） 普通定期：6M-2.45%，9M-2.40%,12M-2.35% 按挂牌利率续存
B15: HLB | D15: =SGD促销!C35 -> - | E15: =SGD促销!C70 -> 0.015 | F15: =SGD促销!C82 -> - | G15: =SGD促销!C93 -> 0.013 | H15: - | I15: - | J15: S100,000 | K15: 按挂牌利率续存
B16: HLF | D16: =SGD促销!C20 -> - | E16: =SGD促销!C57 -> 0.0125 | F16: =SGD促销!C80 -> 0.012 | G16: =SGD促销!C110 -> 0.012 | H16: - | I16: - | J16: 50000 | K16: Fresh FunCs, 手机银行
B17: OCBC | C17: - | D17: =SGD促销!C33 -> 0.014 | E17: =SGD促销!C68 -> - | F17: =SGD促销!C88 -> - | G17: =SGD促销!C115 -> 0.011 | H17: =SGD促销!C134 -> 0.0115 | I17: - | J17: 20000 | K17: internet banking over the counter -0.05%
B18: UOB | C18: - | D18: - | E18: =SGD促销!C53 -> 0.012 | F18: =SGD促销!C84 -> 0.01 | G18: =SGD促销!C112 -> - | H18: - | I18: - | J18: $10,000 | K18: 新资金 按挂牌利率续存
B19: DBS/POSB | C19: =SGD挂牌!C3 -> - | D19: =SGD挂牌!F3 -> 0.0015 | E19: =SGD挂牌!I3 -> 0.008 | F19: =SGD挂牌!L3 -> 0.01 | G19: =SGD挂牌!O3 -> 0.01 | H19: =SGD挂牌!P3 -> 0.01 | I19: =[1]SGD挂牌!Q3 -> 0.01 | J19: - | K19: 挂牌利率
B20: TrustBank | C20: 活期账户：最高2.00%（基础利息0.50%+银行卡消费至少5次，每次30新元0.50%+月均余额100k及以上0.50%+薪水入账0.50%）（cap 1.2M）
B21: GXS | C21: 活期账户：最高1.58%（SG60最多额外1.2%）(cap 60k）
B22: Maribank | C22: 活期账户：最高1.88%，基础利率1.88%（无cap）
B26: 美元促销利率市场调研 | E26: =F2 -> 46099
B27: Bank | C27: 1M | D27: 3M | E27: 6M | F27: 9M | G27: 12M | H27: Minimum Amount | I27: OTHERS
B28: BOC | C28: =USD促销!D6 -> 0.036 | D28: =USD促销!D15 -> 0.036 | E28: =USD促销!D35 -> 0.036 | F28: - | G28: =USD促销!D64 -> 0.0355 | H28: 10000 | I28: ONLINE
B29: ICBC | C29: =USD促销!D5 -> 0.036 | D29: =USD促销!D18 -> 0.0365 | E29: =USD促销!D41 -> 0.036 | F29: - | G29: =USD促销!D60 -> 0.0335 | H29: 500 | I29: ONLINE
B30: CIMB | C30: =USD促销!D7 -> 0.035 | D30: =USD促销!D16 -> 0.036 | E30: =USD促销!D39 -> 0.035 | F30: - | G30: =USD促销!D56 -> 0.034 | H30: 10000 | I30: ONLINE
B31: SCB | C31: =USD促销!D10 -> - | D31: =USD促销!G10 -> - | E31: =USD促销!H10 -> - | F31: =USD促销!D49 -> 0.036 | G31: =USD促销!I10 -> - | H31: 25000 | I31: priority private fresh fund 4.00% personal banking
B32: SBI | C32: - | D32: =USD促销!D25 -> 0 | E32: =USD促销!D43 -> 0.038 | F32: - | G32: =USD促销!D63 -> 0 | H32: 25000 | I32: over the counter
B33: CITI | C33: =USD促销!D8 -> 0.0325 | F33: - | H33: $50,000 | I33: 外币兑换+柜台
B34: RHB | C34: - | D34: - | E34: =USD促销!D42 -> 0.034 | F34: - | G34: =USD促销!D62 -> 0.034 | H34: USD$5,000 | I34: Mobile banking
B35: BEA | C35: =USD促销!D9 -> 0.0325 | D35: =USD促销!D26 -> 0.0345 | E35: =USD促销!D46 -> 0.034 | F35: - | G35: =USD促销!D55 -> 0.0335 | H35: USD$100,000 | I35: personal
B36: HSBC | C36: - | D36: =USD促销!D24 -> 0.03 | E36: =USD促销!D44 -> 0.0285 | F36: - | G36: =USD促销!D58 -> 0.0215 | H36: 30000 | I36: personal
B40: 美元挂牌利率市场调研 | H40: =F2 -> 46099
B41: Bank | C41: 7D | D41: 1M | E41: 3M | F41: 6M | G41: 9M | H41: 12M | I41: 18M | J41: 24M | K41: Minimum Amount | L41: OTHERS | M41: =L3 -> 代表本周有调整
B42: BOC | C42: =USD挂牌!D10 -> 0.027 | D42: =USD挂牌!D38 -> 0.033 | E42: =USD挂牌!D85 -> 0.033 | F42: =USD挂牌!D132 -> 0.0305 | G42: =USD挂牌!D173 -> 0.03 | H42: =USD挂牌!D193 -> 0.029 | I42: =USD挂牌!D234 -> 0.025 | J42: =USD挂牌!D241 -> 0.02 | K42: 500000
B43: ICBC | C43: - | D43: =USD挂牌!D50 -> 0.036 | E43: =USD挂牌!D97 -> 0.0365 | F43: =USD挂牌!D144 -> 0.036 | G43: - | H43: =USD挂牌!D205 -> 0.033 | I43: - | J43: - | K43: 500 | L43: 柜台2万起存，电子银行500起存
B44: DBS/POSB | C44: =USD挂牌!D16 -> 0 | D44: =USD挂牌!D56 -> 0.0348 | E44: =USD挂牌!D103 -> 0.0342 | F44: =USD挂牌!D150 -> 0.0308 | G44: - | H44: =USD挂牌!D211 -> 0.0299 | I44: - | J44: - | K44: 250000
B45: UOB | C45: =USD挂牌!D7 -> 0.0255 | D45: =USD挂牌!D35 -> 0.0324 | E45: =USD挂牌!D82 -> 0.0326 | F45: =USD挂牌!D129 -> 0.0306 | G45: - | H45: =USD挂牌!D190 -> 0.029 | I45: - | J45: - | K45: $250,000-$500,000
B46: Maybank | C46: - | D46: =USD挂牌!D31 -> 0.0315 | E46: =USD挂牌!D78 -> 0.0315 | F46: =USD挂牌!D125 -> 0.0315 | G46: - | H46: - | I46: - | J46: - | K46: 100000
B47: OCBC | C47: - | D47: =USD挂牌!D61 -> 0.0325 | E47: =USD挂牌!D108 -> 0.0325 | F47: =USD挂牌!D155 -> 0.03 | G47: =USD挂牌!D178 -> 0.0293 | H47: =USD挂牌!D216 -> 0.0282 | I47: - | J47: - | K47: 500000
...

Sheet SGD促销
A1: 新元促销利率市场调研
A2: 1 Month
A3: 日期 | C3: ='最高报价汇总 '!F2 -> 46099 | D3: ='最高报价汇总 '!G2 -> 46092 | E3: 46085 | F3: 46078 | G3: 46071 | H3: 46064 | I3: 46057 | J3: 46050 | K3: 46043 | L3: 46036 | M3: 46029 | N3: 46022 | O3: 46015 | P3: 46008 | Q3: 46001 | R3: 45994 | S3: ='最高报价汇总 '!G2 -> 46092 | T3: 45980 | U3: 45973 | V3: 45966 | W3: 45959 | X3: 45952 | Y3: 45945 | Z3: 45938 | AA3: 45931 | AB3: 45924 | AC3: 45917 | AD3: 45910 | AE3: ='最高报价汇总 '!G2 -> 46092 | AF3: 45896 | AG3: 45889 | AH3: 45882 | AI3: 45875 | AJ3: 45868 | AK3: 45861 | AL3: 45854 | AM3: 45847 | AN3: 45840 | AO3: 45833 | AP3: 45826 | AQ3: 45819 | AR3: 45812 | AS3: 45805 | AT3: 45798 | AU3: 45792 | AV3: 45785 | AW3: 45777 | AX3: 45771 | AY3: 45763 | AZ3: 45757 | BA3: 45750 | BB3: 45742 | BC3: ='[2]最高报价汇总 '!H2 -> #REF! | BD3: 45729 | BE3: 45722 | BF3: 45715 | BG3: 45708 | BH3: 45701 | BI3: 45694 | BJ3: 45688 | BK3: 45315 | BL3: 45673 | BM3: 45666 | BN3: 45659 | BO3: 45652 | BP3: 45645 | BQ3: 45638 | BR3: 45631 | BS3: 45625 | BT3: 45617 | BU3: 45610 | BV3: 45603 | BW3: 45595 | BX3: 45591 | BY3: 45582 | BZ3: 45575 | CA3: 45568 | CB3: 45561 | CC3: 45554 | CD3: 45547 | CE3: 45540 | CF3: 45533 | CG3: 45526 | CH3: 45519 | CI3: 45511 | CJ3: 45505 | CK3: 45498 | CL3: 45492 | CM3: 11/7/224 | CN3: 45477 | CO3: 45464 | CP3: 45456 | CQ3: 45449 | CR3: 45442 | CS3: 45435 | CT3: 45428 | CU3: 45421 | CV3: 45414 | CW3: 45407 | CX3: 45400 | CY3: 45393 | CZ3: 45386 | DA3: 45378 | DB3: 45372 | DC3: 45365 | DD3: 45358 | DE3: 45351 | DF3: 45343 | DG3: 45336 | DH3: 45329 | DI3: 45323 | DJ3: 45316 | DK3: 45309 | DL3: 45302 | DM3: 45295 | DN3: 45288 | DO3: 45281 | DP3: 14/21/2023 | DQ3: 45267 | DR3: 45260 | DS3: 45253 | DT3: 45246 | DU3: 45239 | DV3: 45232 | DW3: 45225 | DX3: 45218 | DY3: 45211 | DZ3: 45204 | EA3: 45197 | EB3: 45190 | EC3: 45183 | ED3: 45176 | EE3: 45168 | EF3: 45162 | EG3: 45155 | EH3: 45148 | EI3: 45141 | EJ3: 45134 | EK3: 45127 | EL3: 45120 | EM3: 45113 | EN3: 45105 | EO3: 45099 | EP3: 45092 | EQ3: 45085 | ER3: 45076 | ES3: 45070 | ET3: 45063 | EU3: 45056 | EV3: 45049 | EW3: 45042 | EX3: 45035 | EY3: 45028 | FA3: 44803 | FD3: 44706 | FI3: 44685 | FJ3: 44699 | FK3: 44690 | FL3: 44713 | FM3: 44720 | FN3: 44727 | FO3: 44733 | FP3: 44741 | FQ3: 44755 | FR3: 44748 | FS3: 44769 | FT3: 44762 | FU3: 44783 | FV3: 44776 | FW3: 44797 | FX3: 44790 | FY3: 44805 | FZ3: 45000 | GA3: 44993 | GB3: 44986 | GC3: 44979 | GD3: 44972 | GE3: 44965 | GF3: 44958 | GG3: 44951 | GH3: 44944 | GI3: 44937 | GJ3: 44930 | GK3: 44923 | GL3: 44916 | GM3: 44910 | GN3: 44902 | GO3: 44896 | GP3: 44888 | GQ3: 44881 | GR3: 44874 | GS3: 44868 | GT3: 44860 | GU3: 44853 | GV3: 44846 | GW3: 44839 | GX3: 44831 | GY3: 44825 | GZ3: 44818 | HA3: 44811 | HB3: 45002 | HC3: 45020 | HD3: 45014 | HE3: 45008
B4: 全部公开报价 | C4: 当日最高报价 | D4: 当日最高报价 | E4: 当日最高报价 | F4: 当日最高报价 | G4: 当日最高报价 | H4: 当日最高报价 | I4: 当日最高报价 | J4: 当日最高报价 | K4: 当日最高报价 | L4: 当日最高报价 | M4: 当日最高报价 | N4: 当日最高报价 | O4: 当日最高报价 | P4: 当日最高报价 | Q4: 当日最高报价 | R4: 当日最高报价 | S4: 当日最高报价 | T4: 当日最高报价 | U4: 当日最高报价 | V4: 当日最高报价 | W4: 当日最高报价 | X4: 当日最高报价 | Y4: 当日最高报价 | Z4: 当日最高报价 | AA4: 当日最高报价 | AB4: 当日最高报价 | AC4: 当日最高报价 | AD4: 当日最高报价 | AE4: 当日最高报价 | AF4: 当日最高报价 | AG4: 当日最高报价 | AH4: 当日最高报价 | AI4: 当日最高报价 | AJ4: 当日最高报价 | AK4: 当日最高报价 | AL4: 当日最高报价 | AM4: 当日最高报价 | AN4: 当日最高报价 | AO4: 当日最高报价 | AP4: 当日最高报价 | AQ4: 当日最高报价 | AR4: 当日最高报价 | AS4: 当日最高报价 | AT4: 当日最高报价 | AU4: 当日最高报价 | AV4: 当日最高报价 | AW4: 当日最高报价 | AX4: 当日最高报价 | AY4: 当日最高报价 | AZ4: 当日最高报价 | BA4: 当日最高报价 | BB4: 当日最高报价 | BC4: 当日最高报价 | BD4: 当日最高报价 | BE4: 当日最高报价 | BF4: 当日最高报价 | BG4: 当日最高报价 | BH4: 当日最高报价 | BI4: 当日最高报价 | BJ4: 当日最高报价 | BK4: 当日最高报价 | BL4: 当日最高报价 | BM4: 当日最高报价 | BN4: 当日最高报价 | BO4: 当日最高报价 | BP4: 当日最高报价 | BQ4: 当日最高报价 | BR4: 当日最高报价 | BS4: 当日最高报价 | BT4: 当日最高报价 | BU4: 当日最高报价 | BV4: 当日最高报价 | BW4: 当日最高报价 | BX4: 当日最高报价 | BY4: 当日最高报价 | BZ4: 当日最高报价 | CA4: 当日最高报价 | CB4: 当日最高报价 | CC4: 当日最高报价 | CD4: 当日最高报价 | CE4: 当日最高报价 | CF4: 当日最高报价 | CG4: 当日最高报价 | CH4: 当日最高报价 | CI4: 当日最高报价 | CJ4: 当日最高报价 | CK4: 当日最高报价 | CL4: 当日最高报价 | CM4: 当日最高报价 | CN4: 当日最高报价 | CO4: 当日最高报价 | CP4: 当日最高报价 | CQ4: 当日最高报价 | CR4: 当日最高报价 | CS4: 当日最高报价 | CT4: 当日最高报价 | CU4: 当日最高报价 | CV4: 当日最高报价 | CW4: 当日最高报价 | CX4: 当日最高报价 | CY4: 当日最高报价 | CZ4: 当日最高报价 | DA4: 当日最高报价 | DB4: 当日最高报价 | DC4: 当日最高报价 | DD4: 当日最高报价 | DE4: 当日最高报价 | DF4: 当日最高报价 | DG4: 当日最高报价 | DH4: 当日最高报价 | DI4: 当日最高报价 | DJ4: 当日最高报价 | DK4: 当日最高报价 | DL4: 当日最高报价 | DM4: 当日最高报价 | DN4: 当日最高报价 | DO4: 当日最高报价 | DP4: 当日最高报价 | DQ4: 当日最高报价 | DR4: 当日最高报价 | DS4: 当日最高报价 | DT4: 当日最高报价 | DU4: 当日最高报价 | DV4: 当日最高报价 | DW4: 当日最高报价 | DX4: 当日最高报价 | DY4: 当日最高报价 | DZ4: 当日最高报价 | EA4: 当日最高报价 | EB4: 当日最高报价 | EC4: 当日最高报价 | ED4: 当日最高报价 | EE4: 当日最高报价 | EF4: 当日最高报价 | EG4: 当日最高报价 | EH4: 当日最高报价 | EI4: 当日最高报价 | EJ4: 当日最高报价 | EK4: 当日最高报价 | EL4: 当日最高报价 | EM4: 当日最高报价 | EN4: 当日最高报价 | EO4: 当日最高报价 | EP4: 当日最高报价 | EQ4: 当日最高报价 | ER4: 当日最高报价 | ES4: 当日最高报价 | ET4: 当日最高报价 | EU4: 当日最高报价 | EV4: 当日最高报价 | EW4: 当日最高报价 | EX4: 当日最高报价 | EY4: 当日最高报价 | EZ4: 金额 | FA4: 当日最高报价 | FB4: 全部公开报价 | FC4: 金额 | FD4: 当日最高报价 | FE4: 全部公开报价 | FF4: 金额 | FG4: 挂牌利率/促销利率 | FH4: 当日最高报价 | FI4: 当日最高报价 | FJ4: 当日最高报价 | FK4: 当日最高报价 | FL4: 当日最高报价 | FM4: 当日最高报价 | FN4: 当日最高报价 | FO4: 当日最高报价 | FP4: 当日最高报价 | FQ4: 当日最高报价 | FR4: 当日最高报价 | FS4: 当日最高报价 | FT4: 当日最高报价 | FU4: 当日最高报价 | FV4: 当日最高报价 | FW4: 当日最高报价 | FX4: 当日最高报价 | FY4: 当日最高报价 | FZ4: 当日最高报价 | GA4: 当日最高报价 | GB4: 当日最高报价 | GC4: 当日最高报价 | GD4: 当日最高报价 | GE4: 当日最高报价 | GF4: 当日最高报价 | GG4: 当日最高报价 | GH4: 当日最高报价 | GI4: 当日最高报价 | GJ4: 当日最高报价 | GK4: 当日最高报价 | GL4: 当日最高报价 | GM4: 当日最高报价 | GN4: 当日最高报价 | GO4: 当日最高报价 | GP4: 当日最高报价 | GQ4: 当日最高报价 | GR4: 当日最高报价 | GS4: 当日最高报价 | GT4: 当日最高报价 | GU4: 当日最高报价 | GV4: 当日最高报价 | GW4: 当日最高报价 | GX4: 当日最高报价 | GY4: 当日最高报价 | GZ4: 当日最高报价 | HA4: 当日最高报价 | HB4: 当日最高报价 | HC4: 当日最高报价 | HD4: 当日最高报价 | HE4: 当日最高报价 | HF4: 当日最高报价变动
A5: SCB | B5: >200K | O5: 0.0188 | P5: 0.0188 | Q5: 0.0188 | S5: - | T5: - | U5: - | V5: - | W5: - | X5: - | Y5: - | Z5: - | AA5: - | AB5: - | AC5: - | AD5: - | AE5: - | AF5: - | AG5: - | AH5: - | AI5: - | AJ5: - | AK5: - | AL5: - | AM5: - | AN5: - | AO5: - | AP5: - | AQ5: - | AR5: - | AS5: - | AT5: - | AU5: - | AV5: - | AW5: - | AX5: - | AY5: - | AZ5: - | BA5: - | BB5: - | BC5: - | BD5: - | BE5: - | BF5: - | BG5: - | BH5: - | BI5: - | BJ5: - | BK5: - | BL5: - | BM5: - | BN5: - | BO5: - | BP5: - | BQ5: - | BR5: - | BS5: - | BT5: - | BU5: - | BV5: - | BW5: - | BX5: - | BY5: - | BZ5: - | CA5: - | CB5: - | CC5: - | CD5: - | CE5: - | CF5: - | CG5: - | CH5: - | CI5: - | CJ5: - | CK5: - | CL5: - | CM5: - | CN5: - | CO5: - | CP5: - | CQ5: - | CR5: - | CS5: - | CT5: - | CU5: - | CV5: - | CW5: - | CX5: - | CY5: - | CZ5: - | DA5: - | DB5: - | DC5: - | DD5: - | DE5: - | DF5: - | DG5: - | DH5: - | DI5: - | DJ5: - | DK5: - | DL5: - | DM5: - | DN5: - | DO5: - | DP5: - | DQ5: - | DR5: - | DS5: - | DT5: - | DU5: - | DV5: - | DW5: - | DX5: - | DY5: - | DZ5: - | EA5: - | EB5: - | EC5: - | ED5: - | EE5: - | EF5: - | EG5: - | EH5: - | EI5: - | EJ5: - | EK5: - | EL5: - | EM5: 0.0298 | EN5: 0.0298 | EO5: 0.0298 | EP5: 0.0298 | EQ5: 0.0298 | EZ5: 20,000 < 50,000 | HF5: =C5-D5 -> 0 | HG5: Fresh Fund
EZ6: ≥50,000
A7: BEA | B7: 3.00%fresh fund | C7: - | D7: - | E7: - | F7: - | G7: - | H7: - | I7: - | J7: - | K7: - | L7: - | M7: - | N7: - | O7: - | P7: - | Q7: - | R7: - | S7: - | T7: - | U7: - | V7: - | W7: - | X7: - | Y7: - | Z7: - | AA7: - | AB7: - | AC7: - | AD7: - | AE7: - | AF7: - | AG7: - | AH7: - | AI7: - | AJ7: - | AK7: - | AL7: - | AM7: - | AN7: - | AO7: - | AP7: - | AQ7: - | AR7: - | AS7: - | AT7: - | AU7: - | AV7: - | AW7: - | AX7: - | AY7: - | AZ7: - | BA7: - | BB7: - | BC7: - | BD7: - | BE7: - | BF7: - | BG7: - | BH7: - | BI7: - | BJ7: - | BK7: - | BL7: - | BM7: - | BN7: - | BO7: - | BP7: - | BQ7: - | BR7: - | BS7: - | BT7: - | BU7: - | BV7: - | BW7: - | BX7: - | BY7: - | BZ7: - | CA7: - | CB7: - | CC7: - | CD7: - | CE7: - | CF7: 0.03 | CG7: 0.03 | CH7: 0.03 | CI7: - | CJ7: - | CK7: - | CL7: - | CM7: - | CN7: - | CO7: - | CP7: - | CQ7: - | CR7: - | CS7: - | CT7: - | CU7: - | CV7: - | CW7: - | CX7: - | CY7: - | CZ7: - | DA7: - | DB7: - | DC7: - | DD7: - | DE7: - | DF7: - | DG7: - | DH7: - | DI7: - | DJ7: - | DK7: - | DL7: - | DM7: - | DN7: - | DO7: - | DP7: - | DQ7: - | DR7: - | DS7: - | DT7: - | DU7: - | DV7: - | DW7: - | DX7: - | DY7: 0.028 | DZ7: 0.028 | EA7: 0.028 | EB7: 0.028 | EC7: 0.028 | ED7: 0.028 | EE7: 0.028 | EF7: 0.028 | EG7: 0.028 | EH7: 0.028 | EI7: 0.028 | EJ7: 0.028 | EK7: 0.028 | EL7: 0.028 | EM7: 0.028 | EN7: 0.028 | EO7: 0.028 | EP7: 0.028 | EQ7: 0.028 | ER7: 0.028 | EZ7: 100,000 < 2,000,000 | HF7: -
A8: HSBC | B8: 0.60% personal (counter) 0.65% premier w/o wealth products (counter) 0.9% premier w wealth holdings or FX Engaged (Mobile App only+$30K fresh funds) | C8: 0.006 | D8: 0.006 | E8: 0.006 | F8: 0.0065 | G8: 0.0065 | H8: 0.0065 | I8: 0.0065 | J8: 0.007 | K8: 0.007 | L8: 0.007 | M8: 0.007 | N8: 0.007 | O8: 0.007 | P8: 0.007 | Q8: 0.007 | R8: 0.007 | S8: 0.0085 | T8: 0.0085 | U8: 0.0085 | V8: 0.0085 | W8: 0.0085 | X8: 0.0085 | Y8: 0.0085 | Z8: 0.0085 | AA8: 0.0085 | AB8: 0.0085 | AC8: 0.0085 | AD8: 0.0085 | AE8: 0.01 | AF8: 0.011 | AG8: 0.0115 | AH8: 0.012 | AI8: 0.012 | AJ8: 0.012 | AK8: 0.0095 | AL8: 0.0095 | AM8: 0.0095 | AN8: 0.0095 | HF8: =C8-D8 -> 0
A9: ICBC | B9: 1.10%（online） | C9: 0.0115 | D9: 0.0115 | E9: 0.0115 | F9: 0.0115 | G9: 0.0115 | H9: 0.0115 | I9: 0.0115 | J9: 0.0115 | K9: 0.0115 | L9: 0.0115 | M9: 0.012 | N9: 0.012 | O9: 0.012 | P9: 0.012 | Q9: 0.012 | R9: 0.012 | S9: 0.012 | T9: 0.012 | U9: 0.012 | V9: 0.012 | W9: 0.012 | X9: 0.012 | Y9: 0.012 | Z9: 0.012 | AA9: 0.012 | AB9: 0.012 | AC9: 0.012 | AD9: 0.013 | AE9: 0.013 | AF9: 0.0145 | AG9: 0.0145 | AH9: 0.015 | AI9: 0.015 | AJ9: 0.015 | AK9: 0.015 | AL9: 0.015 | AM9: 0.018 | AN9: 0.018 | AO9: 0.018 | AP9: 0.018 | AQ9: 0.019 | AR9: 0.0205 | AS9: 0.0205 | AT9: 0.0205 | AU9: 2.2%（电子银行） | AV9: 2.2%（电子银行） | AW9: 2.2%（电子银行） | AX9: 2.2%（电子银行） | AY9: 2.2%（电子银行） | AZ9: 2.35%电子/2.35%柜台 | BA9: 2.35%电子/2.35%柜台 | BB9: =BC9 -> 2.8% （电子银行） | BC9: =BD9 -> 2.8% （电子银行） | BD9: =BE9 -> 2.8% （电子银行） | BE9: =BF9 -> 2.8% （电子银行） | BF9: =BG9 -> 2.8% （电子银行） | BG9: =BH9 -> 2.8% （电子银行） | BH9: =BI9 -> 2.8% （电子银行） | BI9: =BJ9 -> 2.8% （电子银行） | ... CB9: =CC9 -> 2.8% （电子银行） | CC9: 2.8% （电子银行） | CD9: 0.029 | CE9: 0.029 | CF9: 0.029 | CG9: 0.029 | CH9: 0.029 | CI9: 0.029 | CJ9: 0.029 | CK9: 0.029 | CL9: 0.029 | CM9: 0.029 | CN9: 0.029 | CO9: 0.029 | CP9: 0.029 | CQ9: 0.029 | CR9: 0.029 | CS9: 0.029 | CT9: 0.029 | CU9: 0.029 | CV9: 0.029 | CW9: 0.029 | CX9: 0.029 | CY9: 0.029 | CZ9: 0.029 | DA9: 0.029 | DB9: 0.029 | DC9: 0.029 | DD9: 0.029 | DE9: 0.029 | DF9: 0.029 | DG9: 0.029 | DH9: 0.029 | DI9: 0.029 | DJ9: 0.029 | DK9: 0.029 | DL9: 0.029 | DM9: 0.029 | DN9: 0.029 | DO9: 0.029 | DP9: 0.029 | DQ9: 0.029 | DR9: 0.029 | DS9: 0.029 | DT9: 0.029 | DU9: 0.029 | DV9: 0.029 | DW9: 0.029 | DX9: 0.029 | DY9: 0.029 | DZ9: 0.029 | EA9: 0.029 | EB9: 0.029 | EC9: 0.029 | ED9: 0.029 | EE9: 0.029 | EF9: 0.029 | EG9: 0.029 | EH9: 0.029 | EI9: 0.029 | EJ9: 0.029 | EK9: 0.029 | EL9: 0.029 | EM9: 0.029 | EN9: 0.029 | EO9: 0.029 | EP9: 0.029 | EQ9: 0.029 | ER9: 0.029 | ES9: 0.029 | ET9: 0.029 | EU9: 0.029 | EV9: 0.029 | EW9: 0.0295 | EX9: 0.031 | EY9: 0.031 | EZ9: ≥20,000 | FA9: 0.006 | FB9: 0.55% 柜面 | FC9: ≥500 | FD9: 0.006 | FE9: 0.55% 柜面 | FF9: ≥500 | FG9: 促销 | FH9: 0.0045 | FI9: 0.0045 | FJ9: 0.0045 | FK9: 0.0045 | FL9: 0.006 | FM9: 0.006 | FN9: 0.006 | FO9: 0.006 | FP9: 0.006 | FQ9: 0.006 | FR9: 0.006 | FS9: 0.006 | FT9: 0.006 | FU9: 0.006 | FV9: 0.006 | FW9: 0.006 | FX9: 0.006 | FY9: 0.0015 | FZ9: 0.031 | GA9: 0.031 | GB9: 0.031 | GC9: 0.036 | GD9: 0.036 | GE9: 0.036 | GF9: 0.036 | GG9: 0.036 | GH9: 0.023 | GI9: 0.023 | GJ9: 0.023 | GK9: 0.023 | GL9: 0.023 | GM9: 0.023 | GN9: 0.023 | GO9: 0.023 | GP9: 0.023 | GQ9: 0.023 | GR9: 0.023 | GS9: 0.0195 | GT9: 0.0195 | GU9: 0.0195 | GV9: 0.0165 | GW9: 0.0165 | GX9: 0.0165 | GY9: 0.0015 | GZ9: 0.0015 | HA9: 0.0015 | HB9: 0.031 | HC9: 0.031 | HD9: 0.031 | HE9: 0.031 | HF9: =C9-D9 -> 0 | HG9: 500-20k
B10: 1.15%（online）>200k | HG10: >200k
A11: BOC | B11: 1.15% (counter) | C11: 0.011 | D11: 0.011 | E11: 0.0115 | F11: 0.0115 | G11: 0.0115 | H11: 0.0115 | I11: 0.0115 | J11: 0.0115 | K11: 0.012 | L11: 0.012 | M11: 0.012 | N11: 0.012 | O11: 0.012 | P11: 0.012 | Q11: 0.012 | R11: 0.012 | S11: 0.012 | T11: 0.012 | U11: 0.012 | V11: 0.012 | W11: 0.012 | X11: 0.012 | Y11: 0.012 | Z11: 0.012 | AA11: 0.012 | AB11: 0.012 | AC11: 0.0125 | AD11: 0.0125 | AE11: 0.0145 | AF11: 0.015 | AG11: 0.0155 | AH11: 0.0155 | AI11: 0.0155 | AJ11: 0.0155 | AK11: 0.017 | AL11: 0.018 | AM11: 0.018 | AN11: 0.018 | AO11: 0.0185 | AP11: 0.02 | AQ11: 0.0205 | AR11: 0.0205 | AS11: 0.021 | AT11: 0.022 | AU11: 0.0225 | AV11: 0.0235 | AW11: 0.0235 | AX11: 0.024 | AY11: 0.024 | AZ11: 0.024 | BA11: 0.024 | BB11: 0.024 | BC11: 0.024 | BD11: 0.025 | BE11: 0.026 | BF11: 0.026 | BG11: 0.026 | BH11: 0.026 | BI11: 0.026 | BJ11: 0.026 | BK11: 0.026 | BL11: 2.6%↓ | BM11: 0.027 | BN11: 0.027 | BO11: 0.027 | BP11: 0.027 | BQ11: 0.027 | BR11: 0.027 | BS11: 0.027 | BT11: 0.027 | BU11: 0.027 | BV11: 0.027 | BW11: 0.027 | BX11: 0.027 | BY11: 0.027 | BZ11: 0.027 | CA11: 0.027 | CB11: 0.0285 | CC11: 0.0295 | CD11: 0.0295 | CE11: 0.0295 | CF11: 0.0295 | CG11: 0.0295 | CH11: 0.0295 | CI11: 0.0295 | CJ11: 0.0295 | CK11: 0.03 | CL11: 0.03 | CM11: 0.03 | CN11: 0.03 | CO11: 0.03 | CP11: 0.03 | CQ11: 0.03 | CR11: 0.03 | CS11: 0.03 | CT11: 0.029 | CU11: 0.029 | CV11: 0.029 | CW11: 0.029 | CX11: 0.029 | CY11: 0.029 | CZ11: 0.029 | DA11: 0.029 | DB11: 0.029 | DC11: 0.029 | DD11: 0.029 | DE11: 0.029 | DF11: 0.029 | DG11: 0.029 | DH11: 0.029 | DI11: 0.029 | DJ11: 0.029 | DK11: 0.029 | DL11: 0.029 | DM11: 0.029 | DN11: 0.029 | DO11: 0.029 | DP11: 0.029 | DQ11: 0.029 | DR11: 0.029 | DS11: 0.029 | DT11: 0.029 | DU11: 0.029 | DV11: 0.029 | DW11: 0.029 | DX11: 0.029 | DY11: 0.029 | DZ11: 0.03 | EA11: 0.03 | EB11: 0.03 | EC11: 0.03 | ED11: 0.03 | EE11: 0.03 | EF11: 0.03 | EG11: 0.03 | EH11: 0.03 | EI11: 0.03 | EJ11: 0.03 | EK11: 0.03 | EL11: 0.03 | EM11: 0.03 | EN11: 0.03 | EO11: 0.03 | EP11: 0.029 | EQ11: 0.029 | ER11: 0.029 | ES11: 0.029 | ET11: 0.029 | EU11: 0.029 | EV11: 0.029 | EW11: 0.029 | EX11: 0.029 | EY11: 0.029 | EZ11: ≥10,000 | FA11: 0.018 | FB11: 0.018 | FC11: ≥5,000 | FD11: 0.006 | FE11: 0.006 | FF11: ≥5千 | FG11: 促销 | FH11: 0.0045 | FI11: 0.0045 | FJ11: 0.006 | FK11: 0.0045 | FL11: 0.006 | FM11: 0.006 | FN11: 0.006 | FO11: 0.006 | FP11: 0.008 | FQ11: 0.01 | FR11: 0.01 | FS11: 0.01 | FT11: 0.01 | FU11: 0.014 | FV11: 0.014 | FW11: 0.016 | FX11: 0.016 | FY11: 0.0145 | FZ11: 0.029 | GA11: 0.029 | GB11: 0.029 | GC11: 0.029 | GD11: 0.029 | GE11: 0.029 | GF11: 0.029 | GG11: 0.0285 | GH11: 0.0285 | GI11: 0.0285 | GJ11: 0.0285 | GK11: 0.0285 | GL11: 0.0285 | GM11: 0.0285 | GN11: 0.0285 | GO11: 0.028 | GP11: 0.027 | GQ11: 0.026 | GR11: 0.023 | GS11: 0.023 | GT11: 0.021 | GU11: 0.021 | GV11: 0.019 | GW11: 0.018 | GX11: 0.0175 | GY11: 0.0165 | GZ11: 0.0165 | HA11: 0.0165 | HB11: 0.029 | HC11: 0.029 | HD11: 0.029 | HE11: 0.029 | HF11: =C11-D11 -> 0
B12: 1.15% (手机银行) | EZ12: ≥500
A13: SingFinance | B13: 1.05%(NewFund 10k) | C13: 0.0105 | D13: 0.0105 | E13: 0.0105 | F13: 0.012 | G13: 0.012 | H13: 0.012 | I13: 0.012 | J13: 0.012 | K13: 0.012 | L13: 0.012 | M13: 0.012 | N13: 0.012 | O13: 0.012 | P13: 0.013 | Q13: 0.013 | R13: 0.013 | S13: 0.013 | T13: 0.013 | U13: 0.013 | V13: 0.013 | W13: - | X13: 0.012 | Y13: 0.012 | Z13: 0.012 | AA13: 0.012 | AB13: 0.012 | AC13: 0.0125 | AD13: 0.0125 | AE13: 0.0145 | AF13: 0.015 | AG13: 0.0155 | AH13: 0.0155 | AI13: 0.0155 | AJ13: 0.0155 | AK13: 0.017 | AL13: 0.018 | AM13: 0.018 | AN13: 0.018 | AO13: 0.0185 | AP13: 0.02 | AQ13: 0.0205 | AR13: 0.0205 | AS13: 0.021 | AT13: 0.022 | AU13: 0.0225 | AV13: 0.0235 | AW13: 0.0235 | AX13: 0.024 | AY13: 0.024 | AZ13: 0.024 | BA13: 0.024 | BB13: 0.024 | BC13: 0.024 | BD13: 0.025 | BE13: 0.026 | BF13: 0.026 | BG13: 0.026 | BH13: 0.026 | BI13: 0.026 | BJ13: 0.026 | BK13: 0.026 | BL13: 2.6%↓ | BM13: 0.027 | BN13: 0.027 | BO13: 0.027 | BP13: 0.027 | BQ13: 0.027 | BR13: 0.027 | BS13: 0.027 | BT13: 0.027 | BU13: 0.027 | BV13: 0.027 | BW13: 0.027 | BX13: 0.027 | BY13: 0.027 | BZ13: 0.027 | CA13: 0.027 | CB13: 0.0285 | CC13: 0.0295 | CD13: 0.0295 | CE13: 0.0295 | CF13: 0.0295 | CG13: 0.0295 | CH13: 0.0295 | CI13: 0.0295 | CJ13: 0.0295 | CK13: 0.03 | CL13: 0.03 | CM13: 0.03 | CN13: 0.03 | CO13: 0.03 | CP13: 0.03 | CQ13: 0.03 | CR13: 0.03 | CS13: 0.03 | CT13: 0.029 | CU13: 0.029 | CV13: 0.029 | CW13: 0.029 | CX13: 0.029 | CY13: 0.029 | CZ13: 0.029 | DA13: 0.029 | DB13: 0.029 | DC13: 0.029 | DD13: 0.029 | DE13: 0.029 | DF13: 0.029 | DG13: 0.029 | DH13: 0.029 | DI13: 0.029 | DJ13: 0.029 | DK13: 0.029 | DL13: 0.029 | DM13: 0.029 | DN13: 0.029 | DO13: 0.029 | DP13: 0.029 | DQ13: 0.029 | DR13: 0.029 | DS13: 0.029 | DT13: 0.029 | DU13: 0.029 | DV13: 0.029 | DW13: 0.029 | DX13: 0.029 | DY13: 0.029 | DZ13: 0.03 | EA13: 0.03 | EB13: 0.03 | EC13: 0.03 | ED13: 0.03 | EE13: 0.03 | EF13: 0.03 | EG13: 0.03 | EH13: 0.03 | EI13: 0.03 | EJ13: 0.03 | EK13: 0.03 | EL13: 0.03 | EM13: 0.03 | EN13: 0.03 | EO13: 0.03 | EP13: 0.029 | EQ13: 0.029 | ER13: 0.029 | ES13: 0.029 | ET13: 0.029 | EU13: 0.029 | EV13: 0.029 | EW13: 0.029 | EX13: 0.029 | EY13: 0.029 | EZ13: ≥10,000 | FA13: 0.018 | FB13: 0.018 | FC13: ≥5,000 | FD13: 0.006 | FE13: 0.006 | FF13: ≥5千 | FG13: 促销 | FH13: 0.0045 | FI13: 0.0045 | FJ13: 0.006 | FK13: 0.0045 | FL13: 0.006 | FM13: 0.006 | FN13: 0.006 | FO13: 0.006 | FP13: 0.008 | FQ13: 0.01 | FR13: 0.01 | FS13: 0.01 | FT13: 0.01 | FU13: 0.014 | FV13: 0.014 | FW13: 0.016 | FX13: 0.016 | FY13: 0.0145 | FZ13: 0.029 | GA13: 0.029 | GB13: 0.029 | GC13: 0.029 | GD13: 0.029 | GE13: 0.029 | GF13: 0.029 | GG13: 0.0285 | GH13: 0.0285 | GI13: 0.0285 | GJ13: 0.0285 | GK13: 0.0285 | GL13: 0.0285 | GM13: 0.0285 | GN13: 0.0285 | GO13: 0.028 | GP13: 0.027 | GQ13: 0.026 | GR13: 0.023 | GS13: 0.023 | GT13: 0.021 | GU13: 0.021 | GV13: 0.019 | GW13: 0.018 | GX13: 0.0175 | GY13: 0.0165 | GZ13: 0.0165 | HA13: 0.0165 | HB13: 0.029 | HC13: 0.029 | HD13: 0.029 | HE13: 0.029 | HF13: =C13-D13 -> 0
B14: 1.0%(NewFund 1k) | EZ14: ≥500
A15: 3 Months
A16: 日期 | C16: =C3 -> 46099 | D16: =D3 -> 46092 | E16: =E3 -> 46085 | F16: =F3 -> 46078 | G16: =G3 -> 46071 | H16: =H3 -> 46064 | I16: =I3 -> 46057 | J16: =J3 -> 46050 | ... AF16: =AF3 -> 45896 | AG16: 45889 | AH16: 45882 | AI16: 45875 | AJ16: 45868 | AK16: 45861 | AL16: 45854 | AM16: 45847 | AN16: 45840 | AO16: =AO3 -> 45833 | AP16: 45826 | AQ16: =AQ3 -> 45819 | AR16: =AR3 -> 45812 | AS16: =AS3 -> 45805 | AT16: =AT3 -> 45798 | AU16: =AU3 -> 45792 | AV16: =AV3 -> 45785 | AW16: =AW3 -> 45777 | AX16: =AX3 -> 45771 | ... EH16: =EH3 -> 45148 | EI16: 45141 | EJ16: 45134 | EK16: 45127 | EL16: 45120 | EM16: 45113 | EN16: 45105 | EO16: 45099 | EP16: 45092 | EQ16: 45085 | ER16: 45076 | ES16: 45070 | ET16: 45063 | EU16: 45056 | EV16: 45049 | EW16: 45042 | EX16: 45035 | EY16: 45028 | FA16: 44803 | FD16: 44706 | FH16: 5月6日 | FI16: 44685 | FJ16: 44699 | FK16: 44690 | FL16: 44713 | FM16: 44720 | FN16: 44727 | FO16: 44733 | FP16: 44741 | FQ16: 44755 | FR16: 44748 | FS16: 44769 | FT16: 44762 | FU16: 44783 | FV16: 44776 | FW16: 44797 | FX16: 44790 | FY16: 44805 | FZ16: 45000 | GA16: 44993 | GB16: 44986 | GC16: 44979 | GD16: 44972 | GE16: 44965 | GF16: 44958 | GG16: 44951 | GH16: 44944 | GI16: 44937 | GJ16: 44930 | GK16: 44923 | GL16: 44916 | GM16: 44910 | GN16: 44902 | GO16: 44896 | GP16: 44888 | GQ16: 44881 | GR16: 44874 | GS16: 44868 | GT16: 44860 | GU16: 44853 | GV16: 44846 | GW16: 44839 | GX16: 44831 | GY16: 44825 | GZ16: 44818 | HA16: 44811 | HB16: 45002 | HC16: 45020 | HD16: 45014 | HE16: 45008
B17: 全部公开报价 | C17: 当日最高报价 | D17: 当日最高报价 | E17: 当日最高报价 | F17: 当日最高报价 | G17: 当日最高报价 | H17: 当日最高报价 | I17: 当日最高报价 | J17: 当日最高报价 | K17: 当日最高报价 | L17: 当日最高报价 | M17: 当日最高报价 | N17: 当日最高报价 | O17: 当日最高报价 | P17: 当日最高报价 | Q17: 当日最高报价 | R17: 当日最高报价 | S17: 当日最高报价 | T17: 当日最高报价 | U17: 当日最高报价 | V17: 当日最高报价 | W17: 当日最高报价 | X17: 当日最高报价 | Y17: 当日最高报价 | Z17: 当日最高报价 | AA17: 当日最高报价 | AB17: 当日最高报价 | AC17: 当日最高报价 | AD17: 当日最高报价 | AE17: 当日最高报价 | AF17: 当日最高报价 | AG17: 当日最高报价 | AH17: 当日最高报价 | AI17: 当日最高报价 | AJ17: 当日最高报价 | AK17: 当日最高报价 | AL17: 当日最高报价 | AM17: 当日最高报价 | AN17: 当日最高报价 | AO17: 当日最高报价 | AP17: 当日最高报价 | AQ17: 当日最高报价 | AR17: 当日最高报价 | AS17: 当日最高报价 | AT17: 当日最高报价 | AU17: 当日最高报价 | AV17: 当日最高报价 | AW17: 当日最高报价 | AX17: 当日最高报价 | AY17: 当日最高报价 | AZ17: 当日最高报价 | BA17: 当日最高报价 | BB17: 当日最高报价 | BC17: 当日最高报价 | BD17: 当日最高报价 | BE17: 当日最高报价 | BF17: 当日最高报价 | BG17: 当日最高报价 | BH17: 当日最高报价 | BI17: 当日最高报价 | BJ17: 当日最高报价 | BK17: 当日最高报价 | BL17: 当日最高报价 | BM17: 当日最高报价 | BN17: 当日最高报价 | BO17: 当日最高报价 | BP17: 当日最高报价 | BQ17: 当日最高报价 | BR17: 当日最高报价 | BS17: 当日最高报价 | BT17: 当日最高报价 | BU17: 当日最高报价 | BV17: 当日最高报价 | BW17: 当日最高报价 | BX17: 当日最高报价 | BY17: 当日最高报价 | BZ17: 当日最高报价 | CA17: 当日最高报价 | CB17: 当日最高报价 | CC17: 当日最高报价 | CD17: 当日最高报价 | CE17: 当日最高报价 | CF17: 当日最高报价 | CG17: 当日最高报价 | CH17: 当日最高报价 | CI17: 当日最高报价 | CJ17: 当日最高报价 | CK17: 当日最高报价 | CL17: 当日最高报价 | CM17: 当日最高报价 | CN17: 当日最高报价 | CO17: 当日最高报价 | CP17: 当日最高报价 | CQ17: 当日最高报价 | CR17: 当日最高报价 | CS17: 当日最高报价 | CT17: 当日最高报价 | CU17: 当日最高报价 | CV17: 当日最高报价 | CW17: 当日最高报价 | CX17: 当日最高报价 | CY17: 当日最高报价 | CZ17: 当日最高报价 | DA17: 当日最高报价 | DB17: 当日最高报价 | DC17: 当日最高报价 | DD17: 当日最高报价 | DE17: 当日最高报价 | DF17: 当日最高报价 | DG17: 当日最高报价 | DH17: 当日最高报价 | DI17: 当日最高报价 | DJ17: 当日最高报价 | DK17: 当日最高报价 | DL17: 当日最高报价 | DM17: 当日最高报价 | DN17: 当日最高报价 | DO17: 当日最高报价 | DP17: 当日最高报价 | DQ17: 当日最高报价 | DR17: 当日最高报价 | DS17: 当日最高报价 | DT17: 当日最高报价 | DU17: 当日最高报价 | DV17: 当日最高报价 | DW17: 当日最高报价 | DX17: 当日最高报价 | DY17: 当日最高报价 | DZ17: 当日最高报价 | EA17: 当日最高报价 | EB17: 当日最高报价 | EC17: 当日最高报价 | ED17: 当日最高报价 | EE17: 当日最高报价 | EF17: 当日最高报价 | EG17: 当日最高报价 | EH17: 当日最高报价 | EI17: 当日最高报价 | EJ17: 当日最高报价 | EK17: 当日最高报价 | EL17: 当日最高报价 | EM17: 当日最高报价 | EN17: 当日最高报价 | EO17: 当日最高报价 | EP17: 当日最高报价 | EQ17: 当日最高报价 | ER17: 当日最高报价 | ES17: 当日最高报价 | ET17: 当日最高报价 | EU17: 当日最高报价 | EV17: 当日最高报价 | EW17: 当日最高报价 | EX17: 当日最高报价 | EY17: 当日最高报价 | EZ17: 金额 | FA17: 当日最高报价 | FB17: 全部公开报价 | FC17: 金额 | FD17: 当日最高报价 | FE17: 全部公开报价 | FF17: 金额 | FG17: 挂牌利率/促销利率 | FH17: 当日最高报价 | FI17: 当日最高报价 | FJ17: 当日最高报价 | FK17: 当日最高报价 | FL17: 当日最高报价 | FM17: 当日最高报价 | FN17: 当日最高报价 | FO17: 当日最高报价 | FP17: 当日最高报价 | FQ17: 当日最高报价 | FR17: 当日最高报价 | FS17: 当日最高报价 | FT17: 当日最高报价 | FU17: 当日最高报价 | FV17: 当日最高报价 | FW17: 当日最高报价 | FX17: 当日最高报价 | FY17: 当日最高报价 | FZ17: 当日最高报价 | GA17: 当日最高报价 | GB17: 当日最高报价 | GC17: 当日最高报价 | GD17: 当日最高报价 | GE17: 当日最高报价 | GF17: 当日最高报价 | GG17: 当日最高报价 | GH17: 当日最高报价 | GI17: 当日最高报价 | GJ17: 当日最高报价 | GK17: 当日最高报价 | GL17: 当日最高报价 | GM17: 当日最高报价 | GN17: 当日最高报价 | GO17: 当日最高报价 | GP17: 当日最高报价 | GQ17: 当日最高报价 | GR17: 当日最高报价 | GS17: 当日最高报价 | GT17: 当日最高报价 | GU17: 当日最高报价 | GV17: 当日最高报价 | GW17: 当日最高报价 | GX17: 当日最高报价 | GY17: 当日最高报价 | GZ17: 当日最高报价 | HA17: 当日最高报价 | HB17: 当日最高报价 | HC17: 当日最高报价 | HD17: 当日最高报价 | HE17: 当日最高报价 | HF17: 当日最高报价变动
A18: CIMB | B18: 1.25% 手机银行 （个人） | C18: 0.0125 | D18: 0.0125 | E18: 0.0125 | F18: 0.013 | G18: 0.013 | H18: 0.013 | I18: 0.013 | J18: 0.013 | K18: 0.013 | L18: 0.013 | M18: 0.013 | N18: 0.013 | O18: 0.013 | P18: 0.013 | Q18: 0.013 | R18: 0.013 | S18: 0.0125 | T18: 0.0125 | U18: 0.0125 | V18: 0.0125 | W18: 0.013 | X18: 0.013 | Y18: 0.013 | Z18: 0.013 | AA18: 0.013 | AB18: 0.013 | AC18: 0.013 | AD18: 0.013 | AE18: 0.014 | AF18: 0.015 | AG18: 0.016 | AH18: 0.016 | AI18: 0.016 | AJ18: 0.017 | AK18: 0.017 | AL18: 0.017 | AM18: 0.0175 | AN18: 0.0185 | AO18: 0.02 | AP18: 0.021 | AQ18: 0.022 | AR18: 0.022 | AS18: 0.0225 | AT18: 0.0225 | AU18: 0.022 | AV18: 0.023 | AW18: 0.0235 | AX18: 0.0235 | AY18: 0.0235 | AZ18: 0.0235 | BA18: 0.0235 | BB18: 0.0245 | BC18: 0.0245 | BD18: 0.0245 | BE18: 0.026 | BF18: 0.0275 | BG18: 0.0275 | BH18: 0.0275 | BI18: 0.0275 | BJ18: 0.027 | BK18: 0.027 | BL18: 0.027 | BM18: 0.027 | BN18: 0.027 | BO18: 0.028 | BP18: 0.028 | BQ18: 0.028 | BR18: 0.028 | BS18: 0.028 | BT18: 0.028 | BU18: 0.028 | BV18: 0.028 | BW18: 0.028 | BX18: 0.028 | BY18: 0.028 | BZ18: 0.028 | CA18: 0.028 | CB18: 0.028 | CC18: 0.03 | CD18: 0.03 | CE18: 0.03 | CF18: 0.031 | CG18: 0.031 | CH18: 0.032 | CI18: 0.032 | CJ18: 0.032 | CK18: 0.033 | CL18: 0.033 | CM18: 0.033 | CN18: 0.033 | CO18: 0.033 | CP18: 0.033 | CQ18: 0.033 | CR18: 0.033 | CS18: 0.033 | CT18: 0.033 | CU18: 0.033 | CV18: 0.033 | CW18: 0.033 | CX18: 0.033 | CY18: 0.033 | CZ18: 0.033 | DA18: 0.0335 | DB18: 0.0335 | DC18: 0.0335 | DD18: 0.0335 | DE18: 0.035 | DF18: 0.035 | DG18: 0.035 | DH18: 0.035 | DI18: 0.035 | DJ18: 0.035 | DK18: 0.035 | DL18: 0.035 | DM18: 0.035 | DN18: 0.035 | DO18: 0.035 | DP18: 0.035 | DQ18: 0.035 | DR18: - | EZ18: ≥10,000 | HF18: =C18-D18 -> 0 | HG18: 10k
B19: 1.30% 手机银行 （财富）
A20: HLF | B20: >60,000 | C20: - | D20: - | E20: - | F20: - | G20: - | H20: - | I20: - | J20: - | K20: - | L20: - | M20: 0.013 | N20: 0.013 | O20: 0.013 | P20: 0.013 | Q20: 0.013 | S20: - | T20: - | U20: - | V20: - | W20: - | X20: - | Y20: - | Z20: - | AA20: - | AB20: - | AC20: - | AD20: - | AE20: - | AF20: - | AG20: - | AH20: - | AI20: - | AJ20: - | AK20: - | AL20: - | AM20: - | AN20: - | AO20: - | AP20: - | AQ20: - | AR20: - | AS20: - | AT20: - | AU20: - | AV20: - | AW20: - | AX20: - | AY20: - | AZ20: - | BA20: - | BB20: - | BC20: - | BD20: - | BE20: - | BF20: - | BG20: - | BH20: - | BI20: - | BJ20: - | BK20: - | BL20: - | BM20: - | BN20: - | BO20: - | BP20: - | BQ20: - | BR20: - | BS20: - | BT20: - | BU20: - | BV20: - | BW20: - | BX20: - | BY20: - | BZ20: - | CA20: - | CB20: - | CC20: - | CD20: - | CE20: - | CF20: - | CG20: - | CH20: - | CI20: - | CJ20: - | CK20: - | CL20: - | CM20: - | CN20: 0.029 | CO20: 0.029 | CP20: 0.029 | CQ20: 0.029 | CR20: 0.029 | CS20: 0.029 | CT20: 0.029 | CU20: 0.029 | CV20: 0.029 | CW20: 0.029 | CX20: 0.0295 | CY20: 0.0295 | CZ20: 0.0295 | DA20: 0.0305 | DB20: 0.0305 | DC20: - | DD20: - | DE20: - | DF20: - | DG20: - | DH20: - | DI20: - | DJ20: - | DK20: - | DL20: - | DM20: - | DN20: - | DO20: - | DP20: - | DQ20: - | DR20: - | DS20: 0.0358 | DT20: 0.0358 | DU20: 0.0358 | DV20: 0.0358 | DW20: 0.0338 | DX20: 0.0338 | DY20: - | DZ20: - | EA20: - | EB20: 3.00%（5-month） | EC20: 3.00%（5-month） | ED20: 3.00%（5-month） | EE20: - | EF20: - | EG20: - | EH20: - | EI20: - | EJ20: - | EK20: - | EL20: - | EM20: 0.0338 | EN20: 0.0338 | EO20: 0.0338 | EP20: 0.0338 | EQ20: 0.0338 | ER20: 0.031 | ES20: 0.031 | ET20: 0.031 | EU20: 0.031 | EZ20: 20,000-50,000 | HF20: =C20-D20 -> #VALUE!
B21: - | EZ21: >= 50,000
A22: CITI | B22: 1.25% (Citigold Client) 1.45% (Citigold Private Client) 1.50% (Citigold Private Client and Citigold 新客户) | C22: 0.0125 | D22: 0.0125 | E22: 0.0125 | F22: 0.013 | G22: 0.013 | H22: 0.013 | I22: - | J22: - | K22: - | L22: - | M22: - | N22: - | O22: - | P22: - | Q22: - | R22: - | S22: - | T22: - | U22: - | V22: - | W22: - | X22: - | Y22: - | Z22: - | AA22: - | AB22: 0.0125 | AC22: 0.0125 | AD22: 0.0125 | AE22: 0.0125 | AF22: 0.014 | AG22: 0.014 | AH22: 0.014 | AI22: 0.014 | AJ22: 0.018 | AK22: 0.018 | AL22: 0.018 | AM22: 0.018 | AN22: 0.018 | AO22: 0.021 | AP22: 0.021 | AQ22: 0.021 | AR22: 0.021 | AS22: 0.02 | AT22: 0.02 | AU22: 0.02 | AV22: 0.02 | AW22: 0.02 | AX22: 0.022 | AY22: 0.022 | AZ22: 0.022 | BA22: 0.022 | BB22: 0.024 | BC22: 0.024 | BD22: 0.024 | BE22: 0.024 | BF22: 0.025 | BG22: 0.025 | BH22: 0.025 | BI22: 0.025 | BJ22: 0.024 | BK22: 0.024 | BL22: 0.024 | BM22: 0.024 | BN22: 0.024 | BO22: 0.024 | BP22: 0.024 | BQ22: 0.024 | BR22: 0.024 | BS22: 0.024 | BT22: 0.024 | BU22: 0.024 | BV22: 0.024 | BW22: 0.0245 | BX22: 0.0245 | BY22: 0.0245 | BZ22: 0.0245 | CA22: 0.0245 | CB22: 0.0255 | CC22: 0.0255 | CD22: 0.0255 | CE22: 0.0255 | CF22: 0.0265 | CG22: 0.0265 | CH22: 0.0265 | CI22: 0.0265 | CJ22: 0.0265 | CK22: 0.025 | CL22: 0.025 | CM22: 0.025 | CN22: 0.025 | CO22: 0.025 | CP22: 0.025 | CQ22: 0.025 | CR22: 0.025 | CS22: 0.025 | CT22: 0.025 | CU22: 0.025 | CV22: 0.025 | CW22: 0.031 | CX22: 0.033 | CY22: 0.033 | CZ22: 0.033 | DA22: 0.033 | DB22: 0.033 | DC22: 0.034 | DD22: 0.034 | DE22: 0.034 | DF22: 0.034 | DG22: 0.035 | DH22: 0.035 | DI22: 0.035 | DJ22: 0.035 | DK22: 0.035 | DL22: 0.035 | DM22: 0.035 | DN22: 0.035 | DO22: 0.035 | DP22: 0.035 | DQ22: 3.7%(citi private) | DR22: 3.7%(citi private) | DS22: 3.7%(citi private) | DT22: 3.7%(citi private) | DU22: 3.7%(citi private) | DV22: 3.7%(citi private) | DW22: 3.2%（Citi priority/citibanking/citi plus） | DX22: 3.5%(citi private) | DY22: 3.5%(citi private) | DZ22: 3.5%(citi private) | EA22: 0.034 | EB22: 0.034 | EC22: 0.034 | ED22: 0.034 | EE22: 0.034 | EF22: 0.034 | EG22: 0.034 | EH22: 0.034 | EI22: 0.034 | EJ22: 0.0368 | EK22: 0.0368 | EL22: 0.0368 | EM22: 0.0368 | EN22: 0.0388 | EO22: 0.0388 | EP22: 0.0388 | EQ22: 0.0388 | ER22: 0.04 | EZ22: 50,000-3,000,000 | HF22: =C22-D22 -> 0 | HG22: Fresh Fund 10k Fresh Fund 350k-10mil
A23: RHB | B23: 1.20% (personal） | C23: 0.012 | D23: 0.012 | E23: 0.012 | F23: 0.012 | G23: 0.012 | H23: 0.012 | I23: 0.0145 | J23: 0.0145 | K23: 0.0145 | L23: 0.0145 | M23: 0.0145 | N23: 0.0145 | O23: 0.0145 | P23: 0.013 | Q23: 0.013 | R23: 0.0115 | S23: 0.0115 | T23: 0.0125 | U23: 0.0125 | V23: 0.0125 | W23: 0.014 | X23: 0.014 | Y23: 0.014 | Z23: 0.014 | AA23: 0.014 | AB23: 0.014 | AC23: 0.014 | AD23: 0.014 | AE23: 0.014 | AF23: 0.014 | AG23: 0.014 | AH23: 0.014 | AI23: 0.015 | AJ23: 0.017 | AK23: 0.017 | AL23: 0.017 | AM23: 0.018 | AN23: 0.018 | AO23: 0.022 | AP23: 0.022 | AQ23: 0.022 | AR23: 0.021 | AS23: 0.021 | AT23: 0.021 | AU23: 0.021 | AV23: 0.021 | AW23: 0.023 | AX23: 0.023 | AY23: 0.023 | AZ23: 0.023 | BA23: 0.023 | BB23: 0.025 | BC23: 0.025 | BD23: 0.025 | BE23: 0.028 | BF23: 0.028 | BG23: 0.028 | BH23: 0.0268 | BI23: 0.0268 | BJ23: 0.0268 | BK23: 0.0268 | BL23: 0.0268 | BM23: 0.03 | BN23: 0.03 | BO23: 0.03 | BP23: 0.03 | BQ23: 0.03 | BR23: 0.03 | BS23: 0.029 | BT23: 0.029 | BU23: 0.0285 | BV23: 0.0285 | BW23: 0.0285 | BX23: 0.0285 | BY23: 0.0285 | BZ23: 0.0275 | CA23: 0.0275 | CB23: 0.0275 | CC23: 0.03 | CD23: 0.03 | CE23: 0.0315 | CF23: 0.0315 | CG23: 0.033 | CH23: 0.033 | CI23: 0.034 | CJ23: 0.034 | CK23: 0.034 | CL23: 0.034 | CM23: 0.034 | CN23: 0.033 | CO23: 0.033 | CP23: 0.033 | CQ23: 0.033 | CR23: 0.033 | CS23: 0.033 | CT23: 0.033 | CU23: 0.033 | CV23: 0.033 | CW23: 0.033 | CX23: 0.031 | CY23: 0.031 | CZ23: 0.031 | DA23: 0.031 | DB23: 0.031 | DC23: 0.031 | DD23: 0.031 | DE23: 0.031 | DF23: 0.031 | DG23: 0.031 | DH23: 0.031 | DI23: 0.031 | DJ23: 0.031 | DK23: 0.031 | DL23: 0.031 | DM23: 0.031 | DN23: 0.031 | DO23: 0.031 | DP23: 0.031 | DQ23: 0.031 | DR23: 0.031 | DS23: 0.031 | DT23: 0.031 | DU23: 0.031 | DV23: 0.031 | DW23: 0.031 | DX23: 0.031 | DY23: 0.031 | DZ23: 0.031 | EA23: 0.031 | EB23: 0.031 | EC23: 0.031 | ED23: 0.031 | EE23: 0.031 | EF23: 0.031 | EG23: 0.031 | EH23: 0.031 | EI23: 0.031 | EJ23: 0.031 | EK23: 0.031 | EL23: 0.031 | EM23: 0.031 | EN23: 0.031 | EO23: 0.031 | EP23: 0.031 | EQ23: 0.031 | ER23: 0.031 | ES23: 0.031 | ET23: 0.031 | EU23: 0.031 | EV23: 0.031 | EW23: 0.034 | EX23: 0.034 | EY23: 0.034 | EZ23: ≥20,000 | FZ23: 0.034 | GA23: 0.034 | GB23: 0.034 | GC23: 0.034 | GD23: 0.0338 | GE23: 0.0338 | GF23: 0.0338 | GG23: 0.0338 | GH23: 0.0338 | GI23: 0.0338 | GJ23: 0.032 | HB23: 0.034 | HC23: 0.034 | HD23: 0.034 | HE23: 0.034 | HF23: =C23-D23 -> 0
B24: 1.30% (premier） | GK24: 0.032 | GL24: 0.032 | GM24: 0.032 | GN24: 0.032 | GO24: 0.032 | GP24: 0.032 | GQ24: 0.032 | GR24: 0.03 | GS24: 0.03 | GT24: 0.03 | GU24: 0.03 | GV24: 0.03 | GW24: - | HG24: 20k | HH24: from 19 Jan 2026
A25: ICBC | B25: 1.15%（online） | C25: 0.0135 | D25: 0.0135 | E25: 0.0135 | F25: 0.0135 | G25: 0.0135 | H25: 0.0135 | I25: 0.0135 | J25: 0.0135 | K25: 0.0135 | L25: 0.0135 | M25: 0.014 | N25: 0.014 | O25: 0.014 | P25: 0.014 | Q25: 0.014 | R25: 0.014 | S25: 0.0125 | T25: 0.0125 | U25: 0.0125 | V25: 0.0125 | W25: 0.0125 | X25: 0.0125 | Y25: 0.0125 | Z25: 0.0125 | AA25: 0.0125 | AB25: 0.0125 | AC25: 0.0125 | AD25: 0.0135 | AE25: 0.0135 | AF25: 0.0145 | AG25: 0.0145 | AH25: 0.015 | AI25: 0.016 | AJ25: 0.016 | AK25: 0.017 | AL25: 0.017 | AM25: 0.0185 | AN25: 0.0185 | AO25: 0.0185 | AP25: 0.0185 | AQ25: 0.0205 | AR25: 0.022 | AS25: 0.022 | AT25: 0.022 | AU25: 2.3%（电子银行） | AV25: 2.3%（电子银行） | AW25: 2.3%（电子银行） | AX25: 2.3%（电子银行） | AY25: 2.3%（电子银行） | AZ25: 2.45%电子/2.45%柜台 | BA25: 2.45%电子/2.45%柜台 | BB25: =#REF! -> #REF! | BC25: =#REF! -> #REF! | BD25: 0.0275 | BE25: 0.0275 | BF25: 0.0275 | BG25: 0.0275 | BH25: 0.029 | BI25: =#REF! -> #REF! | BJ25: =#REF! -> #REF! | BK25: =#REF! -> #REF! | BL25: =#REF! -> #REF! | BM25: =#REF! -> #REF! | BN25: =#REF! -> #REF! | BO25: =#REF! -> #REF! | BP25: =#REF! -> #REF! | ... BV25: =#REF! -> #REF! | BW25: 3.00%电子/3.00%柜台 | BX25: 2.75%电子/2.75%柜台 | BY25: =#REF! -> #REF! | BZ25: 2.75%电子/2.75%柜台 | CA25: =#REF! -> #REF! | CB25: 2.80%电子/2.80%柜台 | CC25: 3.05%（电子银行） | CD25: 3.2%新客户） 3.20%（电子银行） | CE25: 3.3%新客户） 3.25%（电子银行） | CF25: 0.0335 | CG25: 0.0335 | CH25: 0.0345 | CI25: 0.035 | CJ25: 0.035 | CK25: 0.035 | CL25: 0.035 | CM25: 0.035 | CN25: 0.035 | CO25: 0.035 | CP25: 0.035 | CQ25: 0.035 | CR25: 0.035 | CS25: 0.034 | CT25: 0.0335 | CU25: 0.0335 | CV25: 0.0335 | CW25: 0.0335 | CX25: 0.0335 | CY25: 0.0335 | CZ25: 0.0335 | DA25: 0.0335 | DB25: 0.0335 | DC25: 0.0335 | DD25: 0.0335 | DE25: 0.0335 | DF25: 0.0335 | DG25: 0.0335 | DH25: 0.0335 | DI25: 0.0335 | DJ25: 0.0335 | DK25: 0.0335 | DL25: 0.0335 | DM25: 0.0335 | DN25: 0.0335 | DO25: 0.0335 | DP25: 0.0335 | DQ25: 0.0335 | DR25: 0.0335 | DS25: 0.0335 | DT25: 0.0335 | DU25: 0.0335 | DV25: 0.0335 | DW25: 0.0335 | DX25: 0.0335 | DY25: 0.033 | DZ25: 0.033 | EA25: 0.033 | EB25: 0.033 | EC25: 0.033 | ED25: 0.033 | EE25: 0.033 | EF25: 0.033 | EG25: 0.033 | EH25: 0.033 | EI25: 0.033 | EJ25: 0.033 | EK25: 0.035 | EL25: 0.035 | EM25: 0.035 | EN25: 0.035 | EO25: 0.035 | EP25: 0.035 | EQ25: 0.0355 | ER25: 0.0355 | ES25: 0.0355 | ET25: 0.036 | EU25: 0.0365 | EV25: 0.0365 | EW25: 0.0365 | EX25: 0.0375 | EY25: 0.0375 | EZ25: ≥20,000 | FA25: 0.006 | FB25: 0.55% 柜面 | FC25: ≥500 | FD25: 0.006 | FE25: 0.55% 柜面 | FF25: ≥500 | FG25: 促销 | FH25: 0.0045 | FI25: 0.0045 | FJ25: 0.0045 | FK25: 0.0045 | FL25: 0.006 | FM25: 0.006 | FN25: 0.006 | FO25: 0.006 | FP25: 0.006 | FQ25: 0.006 | FR25: 0.006 | FS25: 0.006 | FT25: 0.006 | FU25: 0.006 | FV25: 0.006 | FW25: 0.006 | FX25: 0.006 | FY25: 0.016 | FZ25: 0.0375 | GA25: 0.0375 | GB25: 0.0375 | GC25: 0.039 | GD25: 0.039 | GE25: 0.039 | GF25: 0.039 | GG25: 0.039 | GH25: 0.03 | GI25: 0.03 | GJ25: 0.03 | GK25: 0.03 | GL25: 0.03 | GM25: 0.03 | GN25: 0.03 | GO25: 0.03 | GP25: 0.03 | GQ25: 0.03 | GR25: 0.03 | GS25: 0.0235 | GT25: 0.0235 | GU25: 0.0235 | GV25: 0.02 | GW25: 0.02 | GX25: 0.02 | GY25: 0.016 | GZ25: 0.016 | HA25: 0.016 | HB25: 0.0375 | HC25: 0.0375 | HD25: 0.0375 | HE25: 0.0375 | HF25: =C25-D25 -> 0 | HG25: 500-200k
B26: 1.35%（online）>200k | HG26: >200k
A27: BEA | B27: 1.40% fresh fund | C27: 0.0135 | D27: 0.0135 | E27: 0.0135 | F27: 0.014 | G27: 0.014 | H27: 0.014 | I27: 0.014 | J27: 0.014 | K27: 0.014 | L27: 0.014 | M27: 0.014 | N27: 0.014 | O27: 0.014 | P27: 0.014 | Q27: 0.014 | R27: 0.014 | S27: 0.014 | T27: 0.014 | U27: 0.014 | V27: 0.014 | W27: 0.014 | X27: 0.014 | Y27: 0.014 | Z27: 0.014 | AA27: 0.014 | AB27: 0.014 | AC27: 0.0145 | AD27: 0.0145 | AE27: 0.016 | AF27: 0.016 | AG27: 0.017 | AH27: 0.017 | AI27: 0.018 | AJ27: 0.018 | AK27: 0.018 | AL27: 0.02 | AM27: 0.02 | AN27: 0.021 | AO27: 0.022 | AP27: 0.022 | AQ27: 0.022 | AR27: 0.022 | AS27: 0.0235 | AT27: 0.025 | AU27: 0.025 | AV27: 0.025 | AW27: 0.025 | AX27: 0.025 | AY27: 0.025 | AZ27: 0.025 | BA27: 0.0265 | BB27: 0.0265 | BC27: 0.0265 | BD27: 0.0265 | BE27: 0.0275 | BF27: 0.0275 | BG27: 0.0275 | BH27: 0.029 | BI27: 0.029 | BJ27: 0.029 | BK27: 0.029 | BL27: 0.029 | BM27: 0.03 | BN27: 0.03 | BO27: 0.03 | BP27: 0.03 | BQ27: 0.03 | BR27: 0.029 | BS27: 0.029 | BT27: 0.029 | BU27: 0.029 | BV27: 0.029 | BW27: 0.029 | BX27: 0.029 | BY27: 0.029 | BZ27: 0.031 | CA27: 0.031 | CB27: 0.0295 | CC27: 0.03 | CD27: 0.0325 | CE27: 0.0325 | CF27: 0.0345 | CG27: 0.0345 | CH27: 0.0345 | CI27: 0.035 | CJ27: 0.035 | CK27: 0.034 | CL27: 0.034 | CM27: 0.034 | CN27: 0.034 | CO27: 0.034 | CP27: 0.034 | CQ27: 0.034 | CR27: 0.034 | CS27: 0.034 | CT27: 0.034 | CU27: 0.034 | CV27: 0.034 | CW27: 0.034 | CX27: 0.034 | CY27: 0.034 | CZ27: 0.034 | DA27: 0.034 | DB27: 0.034 | DC27: 0.034 | DD27: 0.034 | DE27: 0.034 | DF27: - | DG27: - | DH27: - | DI27: - | DJ27: - | DK27: - | DL27: - | DM27: - | DN27: - | DO27: - | DP27: - | DQ27: - | DR27: - | DS27: - | DT27: - | DU27: - | DV27: - | DW27: - | DX27: - | DY27: 0.034 | DZ27: 0.034 | EA27: 0.034 | EB27: 0.034 | EC27: 0.034 | ED27: 0.034 | EE27: 0.034 | EF27: 0.034 | EG27: 0.034 | EH27: 0.034 | EI27: 0.034 | EJ27: 0.034 | EK27: 0.034 | EL27: 0.034 | EM27: 0.034 | EN27: 0.034 | EO27: 0.034 | EP27: 0.034 | EQ27: 0.034 | ER27: 0.034 | ES27: 0.034 | ET27: 0.034 | EU27: 0.034 | EV27: 0.034 | EW27: 0.034 | EX27: 0.034 | EY27: 0.034 | EZ27: 100,000-2,000,000 | FZ27: 0.019 | GA27: 0.019 | GB27: 0.019 | GC27: 0.019 | GD27: 0.019 | GE27: 0.019 | GF27: 0.019 | GG27: 0.019 | GH27: 0.019 | GI27: 0.019 | GJ27: 0.019 | GK27: 0.019 | GL27: 0.019 | GM27: 0.019 | GN27: 0.019 | GO27: 0.019 | GP27: 0.019 | GQ27: 0.019 | GR27: 0.019 | GS27: 0.019 | GT27: 0.019 | GU27: 0.019 | GV27: 0.019 | GW27: 0.019 | GX27: 0.019 | HB27: 0.019 | HC27: 0.034 | HD27: 0.034 | HE27: 0.034 | HF27: =C27-D27 -> 0 | HG27: 100k-5mil
A28: HSBC | B28: 0.70% personal (counter) 0.75% premier w/o wealth products (counter) 1.35% premier w wealth holdings or FX Engaged (Mobile App only+$30K fresh funds) 1.40% (mobile banking, fresh fund S$30K) | C28: 0.014 | D28: 0.014 | E28: 0.007 | F28: 0.008 | G28: 0.008 | H28: 0.008 | I28: 0.008 | J28: 0.008 | K28: 0.008 | L28: 0.008 | M28: 0.008 | N28: 0.008 | O28: 0.017 | P28: 0.017 | Q28: 0.016 | R28: 0.016 | S28: 0.016 | T28: 0.016 | U28: 0.016 | V28: 0.008 | W28: 0.008 | X28: 0.008 | Y28: 0.008 | Z28: 0.008 | AA28: 0.008 | AB28: 0.008 | AC28: 0.008 | AD28: 0.008 | AE28: 0.0095 | AF28: 0.0105 | AG28: 0.0105 | AH28: 0.0115 | AI28: 0.0115 | AJ28: 0.0115 | AK28: 0.0085 | AL28: 0.0085 | AM28: 0.0085 | AN28: 0.0105 | AO28: 0.012 | AP28: 0.012 | AQ28: 0.014 | AR28: 0.014 | AS28: 0.0155 | AT28: 0.02 | AU28: 0.0155 | AV28: 0.016 | AW28: 0.016 | AX28: 0.016 | AY28: 0.019 | AZ28: 0.019 | BA28: 0.019 | BB28: 0.022 | BC28: 0.022 | BD28: 0.022 | BE28: 0.024 | BF28: 0.024 | BG28: 0.024 | BH28: 0.024 | BI28: 0.024 | BJ28: 0.0258 | BK28: 0.0258 | BL28: 0.0258 | BM28: 2.58%↓ | BN28: 0.0265 | BO28: 0.0265 | BP28: 0.0265 | BQ28: 0.0265 | BR28: 0.0265 | BS28: 0.0275 | BT28: 0.0275 | BU28: 0.0275 | BV28: 0.0275 | BW28: 0.0275 | BX28: 0.0275 | BY28: 2.9%（4M) | BZ28: 2.9%（4M) | CA28: 2.9%（4M) | CB28: 3.3%（4M) | CC28: 3.3%（4M) | CD28: 3.1%（4M) | CE28: 3.1%（4M) | CF28: - | EZ28: 30,000-100,000 | HF28: =C28-D28 -> 0
A29: BOC | B29: 1.15% (counter) | C29: 0.013 | D29: 0.013 | E29: 0.013 | F29: 0.013 | G29: 0.013 | H29: 0.0135 | I29: 0.0135 | J29: 0.0135 | K29: 0.0135 | L29: 0.014 | M29: 0.014 | N29: 0.014 | O29: 0.014 | P29: 0.014 | Q29: 0.014 | R29: 0.014 | S29: 0.014 | T29: 0.014 | U29: 0.014 | V29: 0.014 | W29: 0.014 | X29: 0.014 | Y29: 0.013 | Z29: 0.013 | AA29: 0.013 | AB29: 0.013 | AC29: 0.0135 | AD29: 0.0135 | AE29: 0.0145 | AF29: 0.0155 | AG29: 0.0165 | AH29: 0.017 | AI29: 0.017 | AJ29: 0.017 | AK29: 0.018 | AL29: 0.0182 | AM29: 0.0186 | AN29: 0.0195 | AO29: 0.02 | AP29: 0.02 | AQ29: 0.021 | AR29: 0.021 | AS29: 0.0215 | AT29: 0.0225 | AU29: 0.023 | AV29: 0.0235 | AW29: 0.024 | AX29: 0.0245 | AY29: 0.025 | AZ29: 0.025 | BA29: 0.025 | BB29: 0.025 | BC29: 0.025 | BD29: 0.0265 | BE29: 0.0275 | BF29: 0.0275 | BG29: 0.0275 | BH29: 0.028 | BI29: 0.028 | BJ29: 0.028 | BK29: 0.029 | BL29: 2.95%↓ | BM29: 0.03 | BN29: 0.03 | BO29: 0.03 | BP29: 0.03 | BQ29: 0.03 | BR29: 0.03 | BS29: 0.03 | BT29: 0.03 | BU29: 0.03 | BV29: 0.0305 | BW29: 0.0305 | BX29: 0.0305 | BY29: 0.031 | BZ29: 0.03 | CA29: 0.029 | CB29: 0.0305 | CC29: 0.0315 | CD29: 0.0315 | CE29: 0.032 | CF29: 0.0335 | CG29: 0.0335 | CH29: 0.0335 | CI29: 0.034 | CJ29: 0.0345 | CK29: 0.035 | CL29: 0.035 | CM29: 0.035 | CN29: 0.035 | CO29: 0.035 | CP29: 0.035 | CQ29: 0.035 | CR29: 0.034 | CS29: 0.034 | CT29: 0.033 | CU29: 0.033 | CV29: 0.033 | CW29: 0.0335 | CX29: 0.0335 | CY29: 0.0335 | CZ29: 0.0335 | DA29: 0.0335 | DB29: 0.034 | DC29: 0.034 | DD29: 0.034 | DE29: 0.034 | DF29: 0.034 | DG29: 0.0345 | DH29: 0.0345 | DI29: 0.0345 | DJ29: 0.0345 | DK29: 0.035 | DL29: 0.036 | DM29: 0.036 | DN29: 0.036 | DO29: 0.036 | DP29: 0.036 | DQ29: 0.036 | DR29: 0.0355 | DS29: 0.035 | DT29: 0.0345 | DU29: 0.0345 | DV29: 0.0335 | DW29: 0.0335 | DX29: 0.0335 | DY29: 0.0335 | DZ29: 0.034 | EA29: 0.034 | EB29: 0.034 | EC29: 0.0345 | ED29: 0.035 | EE29: 0.035 | EF29: 0.035 | EG29: 0.035 | EH29: 0.035 | EI29: 0.035 | EJ29: 0.035 | EK29: 0.035 | EL29: 0.035 | EM29: 0.035 | EN29: 0.035 | EO29: 0.035 | EP29: 0.035 | EQ29: 0.035 | ER29: 0.035 | ES29: 0.035 | ET29: 0.0355 | EU29: 0.0355 | EV29: 0.036 | EW29: 0.036 | EX29: 0.0365 | EY29: 0.037 | EZ29: ≥10,000 | FY29: 0.018 | FZ29: 0.0375 | GA29: 0.0375 | GB29: 0.0375 | GC29: 0.0375 | GD29: 0.038 | GE29: 0.038 | GF29: 0.039 | GG29: 0.038 | GH29: 0.038 | GI29: 0.038 | GJ29: 0.037 | GK29: 0.037 | GL29: 0.037 | GM29: 0.037 | GN29: 0.037 | GO29: 0.0365 | GP29: 0.036 | GQ29: 0.032 | GR29: 0.03 | GS29: 0.03 | GT29: 0.027 | GU29: 0.027 | GV29: 0.023 | GW29: 0.0215 | GX29: 0.021 | GY29: 0.02 | GZ29: 0.02 | HA29: 0.02 | HB29: 0.0375 | HC29: 0.037 | HD29: 0.0375 | HE29: 0.0375 | HF29: =C29-D29 -> 0
B30: 1.30% (手机银行) | EZ30: ≥500 | FA30: 0.018 | FB30: 0.018 | FC30: ≥5,000 | FD30: 0.006 | FE30: 0.006 | FF30: ≥5千 | FG30: 促销 | FH30: 0.0045 | FI30: 0.0045 | FJ30: 0.006 | FK30: 0.0045 | FL30: 0.006 | FM30: 0.006 | FN30: 0.006 | FO30: 0.006 | FP30: 0.008 | FQ30: 0.01 | FR30: 0.01 | FS30: 0.01 | FT30: 0.01 | FU30: 0.014 | FV30: 0.014 | FW30: 0.016 | FX30: 0.016
A31: SingFinance | B31: 1.25%(NewFund 10k) | C31: 0.0125 | D31: 0.0125 | E31: 0.0125 | F31: 0.013 | G31: 0.013 | H31: 0.013 | I31: 0.013 | J31: 0.013 | K31: 0.013 | L31: 0.013 | M31: 0.013 | N31: 0.013 | O31: 0.013 | P31: 0.014 | Q31: 0.014 | R31: 0.014 | S31: 0.014 | T31: 0.013 | U31: 0.012 | V31: 0.012 | W31: 0.012 | X31: 0.012 | Y31: 0.012 | Z31: 0.012 | AA31: 0.012 | AB31: 0.012 | AC31: 0.012 | AD31: 0.014 | AE31: 0.014 | AF31: 0.015 | AG31: 0.0155 | AH31: 0.016 | AI31: 0.016 | AJ31: 0.0165 | AK31: 0.0165 | AL31: 0.0165 | AM31: 0.0175 | AN31: 0.0175 | AO31: 0.0185 | AP31: 0.0195 | AQ31: 0.0205 | AR31: 0.0205 | AS31: 0.0205 | AT31: 0.0205 | AU31: 0.0205 | AV31: 0.0205 | AW31: 0.0205 | AX31: 0.022 | AY31: 0.023 | AZ31: 0.023 | BA31: 0.0245 | BB31: 0.0245 | BC31: 0.0255 | BD31: 0.0255 | BE31: 0.0265 | BF31: 0.0265 | BG31: 0.0265 | BH31: 0.027 | BI31: 0.027 | BJ31: 0.027 | BK31: 0.027 | BL31: 0.027 | BM31: 0.027 | BN31: 0.027 | BO31: 0.027 | BP31: 0.027 | BQ31: 0.027 | BR31: 0.027 | BS31: 0.027 | BT31: 0.027 | BU31: 0.027 | BV31: 0.027 | BW31: 0.027 | BX31: 0.027 | BY31: 0.027 | BZ31: 0.027 | CA31: 0.027 | CB31: 0.027 | CC31: 0.0275 | CD31: 0.0275 | CE31: 0.0275 | CF31: 0.0285 | CG31: 0.0285 | CH31: 0.0295 | CI31: 0.0295 | CJ31: 0.0295 | CK31: 0.0295 | CL31: 0.0295 | CM31: 0.0295 | CN31: 0.0295 | CO31: 0.03 | CP31: 0.03 | CQ31: 0.03 | CR31: 0.03 | CS31: 0.03 | CT31: 0.03 | CU31: 0.03 | CV31: 0.03 | CW31: 0.03 | CX31: 0.03 | CY31: 0.03 | CZ31: 0.03 | DA31: 0.03 | DB31: 0.03 | DC31: 0.0305 | DD31: 0.0305 | DE31: 0.0305 | DF31: 0.03 | DG31: 0.03 | DH31: 0.03 | DI31: 0.03 | DJ31: 0.0318 | DK31: 0.0318 | DL31: 0.0335 | DM31: 0.034 | DN31: 0.034 | DO31: 0.034 | DP31: 0.034 | DQ31: 0.034 | DR31: 0.034 | DS31: 0.033 | DT31: 0.033 | DU31: 0.033 | DV31: 0.032 | DW31: 0.03 | DX31: 0.03 | DY31: 0.03 | DZ31: 0.03 | EA31: 0.032 | EB31: 0.032 | EC31: 0.032 | ED31: 0.032 | EE31: 0.032 | EF31: 0.032 | EG31: 0.032 | EH31: 0.032 | EI31: - | EJ31: - | EK31: - | EL31: 0.03 | EM31: 0.031 | EN31: 0.031 | EO31: 0.031 | EP31: 0.031 | EQ31: 0.031 | ER31: 0.033 | ES31: 0.033 | ET31: 0.033 | EU31: 0.0345 | EV31: 0.0345 | EW31: 0.0355 | EX31: 0.0355 | EY31: 0.0355 | EZ31: ≥10,000 | FA31: - | FB31: - | FC31: ≥10,000 | FS31: 0.002 | FU31: 0.0138 | FV31: 0.0138 | FW31: 0.0138 | FX31: 0.0138 | FY31: - | FZ31: - | GA31: - | GB31: - | GC31: - | GD31: - | GE31: - | GF31: - | GG31: - | GH31: - | GI31: - | GJ31: - | GK31: - | GL31: - | GM31: - | GN31: - | GO31: - | GP31: - | GQ31: - | GR31: - | GS31: - | GT31: - | GU31: - | GV31: - | GW31: - | GX31: - | GY31: - | GZ31: - | HA31: - | HB31: - | HC31: 0.0355 | HD31: - | HE31: - | HF31: =C31-D31 -> 0
B32: 1.20%(NewFund 1k) | EZ32: ≥1,000
A33: OCBC | B33: 1.40%（fresh fund 50k-3mil）88 days | C33: 0.014 | D33: 0.014 | E33: 0.014 | F33: 0.016 | G33: 0.016 | H33: 0.016 | I33: 0.016 | J33: 0.018 | K33: 0.018 | L33: 0.018 | M33: 0.018 | N33: 0.018 | O33: 0.0145 | P33: 0.0145 | Q33: 0.0145 | R33: 0.0145 | S33: 0.0155 | T33: 0.0155 | U33: 0.0155 | V33: 0.0155 | W33: 0.0178 | X33: 0.0178 | Y33: 0.0178 | Z33: 0.0178 | AA33: 0.0178 | HF33: =C33-D33 -> 0
B34: 1.35%（fresh fund 25k-3000k） | AB34: 0.0188 | AC34: 0.0188 | AD34: 0.0208 | AE34: 0.0208 | AF34: 0.0208 | AG34: 0.0208 | AH34: - | AI34: - | AJ34: - | AK34: - | AL34: - | AM34: - | AN34: - | AO34: - | AP34: - | AQ34: - | AR34: - | AS34: - | AT34: - | AU34: - | AV34: - | AW34: - | AX34: - | AY34: - | AZ34: - | BA34: - | BB34: - | BC34: - | BD34: - | BE34: - | BF34: - | BG34: - | BH34: - | BI34: - | BJ34: - | BK34: - | BL34: - | BM34: - | BN34: - | BO34: - | BP34: - | BQ34: - | BR34: - | BS34: - | BT34: - | BU34: - | BV34: - | BW34: - | BX34: - | BY34: - | BZ34: - | CA34: - | CB34: - | CC34: - | CD34: - | CE34: - | CF34: - | CG34: - | CH34: - | CI34: - | CJ34: - | CK34: - | CL34: - | CM34: - | CN34: - | CO34: - | CP34: - | CQ34: - | CR34: - | CS34: - | CT34: - | CU34: - | CV34: - | CW34: - | CX34: - | CY34: - | CZ34: - | DA34: - | DB34: - | DC34: - | DD34: - | DE34: - | DF34: - | DG34: - | DH34: - | DI34: - | DJ34: - | DK34: - | DL34: - | DM34: - | DN34: - | DO34: - | DP34: - | DQ34: - | DR34: - | DS34: - | DT34: - | DU34: - | DV34: - | DW34: - | DX34: - | DY34: - | DZ34: - | EA34: - | EB34: - | EC34: - | ED34: - | EE34: - | EF34: - | EG34: - | EH34: - | EI34: - | EJ34: - | EK34: - | EL34: - | EM34: - | EN34: - | EO34: - | EP34: - | EQ34: - | ER34: - | ES34: - | ET34: - | EU34: - | EV34: - | EW34: - | EX34: - | EY34: - | EZ34: - | FA34: - | FB34: - | FC34: - | FD34: - | FE34: - | FF34: - | FG34: - | FH34: - | FI34: - | FJ34: - | FK34: - | FL34: - | FM34: - | FN34: - | FO34: - | FP34: - | FQ34: - | FR34: - | FS34: - | FT34: - | FU34: - | FV34: - | FW34: - | FX34: - | FY34: - | FZ34: - | GA34: - | GB34: - | GC34: - | GD34: - | GE34: - | GF34: - | GG34: - | GH34: - | GI34: - | GJ34: - | GK34: - | GL34: - | GM34: - | GN34: - | GO34: - | GP34: - | GQ34: - | GR34: - | GS34: - | GT34: - | GU34: - | GV34: - | GW34: - | GX34: - | GY34: - | GZ34: - | HA34: - | HB34: - | HC34: - | HD34: - | HE34: -
A35: HLB | B35: 1.50%(Online S$10K) 1.50%(Others S$100K) | C35: - | D35: - | E35: - | F35: - | G35: - | H35: - | I35: - | J35: - | K35: - | L35: - | M35: - | N35: - | O35: 0.015 | P35: 0.015 | HF35: =C35-D35 -> #VALUE!
A36: 6 Months
A37: 日期 | C37: =C3 -> 46099 | D37: =D3 -> 46092 | E37: =E3 -> 46085 | F37: =F3 -> 46078 | G37: =G3 -> 46071 | H37: =H3 -> 46064 | I37: =I3 -> 46057 | J37: =J3 -> 46050 | ... AF37: =AF3 -> 45896 | AG37: 45889 | AH37: 45882 | AI37: 45875 | AJ37: 45868 | AK37: 45861 | AL37: 45854 | AM37: 45847 | AN37: 45840 | AO37: =AO3 -> 45833 | AP37: 45826 | AQ37: =AQ3 -> 45819 | AR37: =AR3 -> 45812 | AS37: =AS3 -> 45805 | AT37: =AT3 -> 45798 | AU37: =AU3 -> 45792 | AV37: =AV3 -> 45785 | AW37: =AW3 -> 45777 | AX37: =AX3 -> 45771 | ... EH37: =EH3 -> 45148 | EI37: 45141 | EJ37: 45134 | EK37: 45127 | EL37: 45120 | EM37: 45113 | EN37: 45105 | EO37: 45099 | EP37: 45092 | EQ37: 45085 | ER37: 45076 | ES37: 45070 | ET37: 45063 | EU37: 45056 | EV37: 45049 | EW37: 45042 | EX37: 45035 | EY37: 45028 | FA37: 44803 | FD37: 44706 | FH37: 5月6日 | FI37: 44685 | FJ37: 44699 | FK37: 44690 | FL37: 44713 | FM37: 44720 | FN37: 44727 | FO37: 44733 | FP37: 44741 | FQ37: 44755 | FR37: 44748 | FS37: 44769 | FT37: 44762 | FU37: 44783 | FV37: 44776 | FW37: 44797 | FX37: 44790 | FY37: 44805 | FZ37: 45000 | GA37: 44993 | GB37: 44986 | GC37: 44979 | GD37: 44972 | GE37: 44965 | GF37: 44958 | GG37: 44951 | GH37: 44944 | GI37: 44937 | GJ37: 44930 | GK37: 44923 | GL37: 44916 | GM37: 44910 | GN37: 44902 | GO37: 44896 | GP37: 44888 | GQ37: 44881 | GR37: 44874 | GS37: 44868 | GT37: 44860 | GU37: 44853 | GV37: 44846 | GW37: 44839 | GX37: 44831 | GY37: 44825 | GZ37: 44818 | HA37: 44811 | HB37: 45002 | HC37: 45020 | HD37: 45014 | HE37: 45008
B38: 全部公开报价 | C38: 当日最高报价 | D38: 当日最高报价 | E38: 当日最高报价 | F38: 当日最高报价 | G38: 当日最高报价 | H38: 当日最高报价 | I38: 当日最高报价 | J38: 当日最高报价 | K38: 当日最高报价 | L38: 当日最高报价 | M38: 当日最高报价 | N38: 当日最高报价 | O38: 当日最高报价 | P38: 当日最高报价 | Q38: 当日最高报价 | R38: 当日最高报价 | S38: 当日最高报价 | T38: 当日最高报价 | U38: 当日最高报价 | V38: 当日最高报价 | W38: 当日最高报价 | X38: 当日最高报价 | Y38: 当日最高报价 | Z38: 当日最高报价 | AA38: 当日最高报价 | AB38: 当日最高报价 | AC38: 当日最高报价 | AD38: 当日最高报价 | AE38: 当日最高报价 | AF38: 当日最高报价 | AG38: 当日最高报价 | AH38: 当日最高报价 | AI38: 当日最高报价 | AJ38: 当日最高报价 | AK38: 当日最高报价 | AL38: 当日最高报价 | AM38: 当日最高报价 | AN38: 当日最高报价 | AO38: 当日最高报价 | AP38: 当日最高报价 | AQ38: 当日最高报价 | AR38: 当日最高报价 | AS38: 当日最高报价 | AT38: 当日最高报价 | AU38: 当日最高报价 | AV38: 当日最高报价 | AW38: 当日最高报价 | AX38: 当日最高报价 | AY38: 当日最高报价 | AZ38: 当日最高报价 | BA38: 当日最高报价 | BB38: 当日最高报价 | BC38: 当日最高报价 | BD38: 当日最高报价 | BE38: 当日最高报价 | BF38: 当日最高报价 | BG38: 当日最高报价 | BH38: 当日最高报价 | BI38: 当日最高报价 | BJ38: 当日最高报价 | BK38: 当日最高报价 | BL38: 当日最高报价 | BM38: 当日最高报价 | BN38: 当日最高报价 | BO38: 当日最高报价 | BP38: 当日最高报价 | BQ38: 当日最高报价 | BR38: 当日最高报价 | BS38: 当日最高报价 | BT38: 当日最高报价 | BU38: 当日最高报价 | BV38: 当日最高报价 | BW38: 当日最高报价 | BX38: 当日最高报价 | BY38: 当日最高报价 | BZ38: 当日最高报价 | CA38: 当日最高报价 | CB38: 当日最高报价 | CC38: 当日最高报价 | CD38: 当日最高报价 | CE38: 当日最高报价 | CF38: 当日最高报价 | CG38: 当日最高报价 | CH38: 当日最高报价 | CI38: 当日最高报价 | CJ38: 当日最高报价 | CK38: 当日最高报价 | CL38: 当日最高报价 | CM38: 当日最高报价 | CN38: 当日最高报价 | CO38: 当日最高报价 | CP38: 当日最高报价 | CQ38: 当日最高报价 | CR38: 当日最高报价 | CS38: 当日最高报价 | CT38: 当日最高报价 | CU38: 当日最高报价 | CV38: 当日最高报价 | CW38: 当日最高报价 | CX38: 当日最高报价 | CY38: 当日最高报价 | CZ38: 当日最高报价 | DA38: 当日最高报价 | DB38: 当日最高报价 | DC38: 当日最高报价 | DD38: 当日最高报价 | DE38: 当日最高报价 | DF38: 当日最高报价 | DG38: 当日最高报价 | DH38: 当日最高报价 | DI38: 当日最高报价 | DJ38: 当日最高报价 | DK38: 当日最高报价 | DL38: 当日最高报价 | DM38: 当日最高报价 | DN38: 当日最高报价 | DO38: 当日最高报价 | DP38: 当日最高报价 | DQ38: 当日最高报价 | DR38: 当日最高报价 | DS38: 当日最高报价 | DT38: 当日最高报价 | DU38: 当日最高报价 | DV38: 当日最高报价 | DW38: 当日最高报价 | DX38: 当日最高报价 | DY38: 当日最高报价 | DZ38: 当日最高报价 | EA38: 当日最高报价 | EB38: 当日最高报价 | EC38: 当日最高报价 | ED38: 当日最高报价 | EE38: 当日最高报价 | EF38: 当日最高报价 | EG38: 当日最高报价 | EH38: 当日最高报价 | EI38: 当日最高报价 | EJ38: 当日最高报价 | EK38: 当日最高报价 | EL38: 当日最高报价 | EM38: 当日最高报价 | EN38: 当日最高报价 | EO38: 当日最高报价 | EP38: 当日最高报价 | EQ38: 当日最高报价 | ER38: 当日最高报价 | ES38: 当日最高报价 | ET38: 当日最高报价 | EU38: 当日最高报价 | EV38: 当日最高报价 | EW38: 当日最高报价 | EX38: 当日最高报价 | EY38: 当日最高报价 | EZ38: 金额 | FA38: 当日最高报价 | FB38: 全部公开报价 | FC38: 金额 | FD38: 当日最高报价 | FE38: 全部公开报价 | FF38: 金额 | FG38: 挂牌利率/促销利率 | FH38: 当日最高报价 | FI38: 当日最高报价 | FJ38: 当日最高报价 | FK38: 当日最高报价 | FL38: 当日最高报价 | FM38: 当日最高报价 | FN38: 当日最高报价 | FO38: 当日最高报价 | FP38: 当日最高报价 | FQ38: 当日最高报价 | FR38: 当日最高报价 | FS38: 当日最高报价 | FT38: 当日最高报价 | FU38: 当日最高报价 | FV38: 当日最高报价 | FW38: 当日最高报价 | FX38: 当日最高报价 | FY38: 当日最高报价 | FZ38: 当日最高报价 | GA38: 当日最高报价 | GB38: 当日最高报价 | GC38: 当日最高报价 | GD38: 当日最高报价 | GE38: 当日最高报价 | GF38: 当日最高报价 | GG38: 当日最高报价 | GH38: 当日最高报价 | GI38: 当日最高报价 | GJ38: 当日最高报价 | GK38: 当日最高报价 | GL38: 当日最高报价 | GM38: 当日最高报价 | GN38: 当日最高报价 | GO38: 当日最高报价 | GP38: 当日最高报价 | GQ38: 当日最高报价 | GR38: 当日最高报价 | GS38: 当日最高报价 | GT38: 当日最高报价 | GU38: 当日最高报价 | GV38: 当日最高报价 | GW38: 当日最高报价 | GX38: 当日最高报价 | GY38: 当日最高报价 | GZ38: 当日最高报价 | HA38: 当日最高报价 | HB38: 当日最高报价 | HC38: 当日最高报价 | HD38: 当日最高报价 | HE38: 当日最高报价 | HF38: 当日最高报价变动
